Workbook
Name \0: #REF!
Name \a: #REF!
Name \b: #REF!
Name \c: #REF!
Name \d: #REF!
Name \e: #REF!
Name \f: #N/A
Name \g: #N/A
Name \h: #N/A
Name \i: #N/A
Name \j: #N/A
Name \k: #N/A
Name \l: #REF!
Name \n: #REF!
Name \o: #N/A
Name \p: #REF!
Name \r: #N/A
Name \s: #REF!
Name \t: #REF!
Name \u: #REF!
Name \w: #REF!
Name \x: #REF!
Name \y: #REF!
Name \z: #N/A
Name __1CTLマクロ_.NitteiSave_終了: #REF!
Name __2CTLマクロ_.Scroll_L: #REF!
Name __3CTLマクロ_.Scroll_LBK: #REF!
Name __4CTLマクロ_.ScrollForm: #REF!
Name __5CTLマクロ_.日程表_Copy: #REF!
Name __g01: #REF!,#REF!
Name __g02: #REF!,#REF!
Name __g03: #REF!,#REF!
Name __g04: #REF!,#REF!
Name __g05: #REF!,#REF!
Name __g06: #REF!,#REF!
Name __g07: #REF!,#REF!
Name __g08: #REF!,#REF!
Name __g09: #REF!,#REF!
Name __g10: #REF!,#REF!
Name __g11: #REF!,#REF!,#REF!
Name __g12: #REF!,#REF!
Name __g13: #REF!,#REF!
Name __g14: #REF!,#REF!
Name __m01: #REF!,#REF!
Name __m02: #REF!,#REF!
Name __m03: #REF!,#REF!
Name __m04: #REF!,#REF!
Name __m05: #REF!,#REF!
Name __m06: #REF!,#REF!
Name __m07: #REF!,#REF!
Name __m08: #REF!,#REF!
Name __m09: #REF!,#REF!
Name __m10: #REF!,#REF!
Name __m11: #REF!,#REF!
Name __m12: #REF!,#REF!
Name __m13: #REF!,#REF!
Name __m14: #REF!,#REF!
Name __m15: #REF!,#REF!
Name __m16: #REF!,#REF!
Name __Oct99: #REF!

Sheet LCM
A1: Lower of Cost or Market Analysis | K1: March 31, 2022
A4: FG | J4: Total LCA Amount | K4: =SUM(K6:K1078) -> #REF!
B5: Back # | C5: Parts # | D5: Material Cost | E5: Process Cost | F5: Total Cost | H5: Sales Price | I5: OK or NG | J5: Ending QTY | K5: LCA
B6: 030-05 | C6: 79030-0K010-E1 | D6: =VLOOKUP(B6,FG!$A$5:$H$1158,12,FALSE) -> #REF! | E6: =IF(J6<=0,0,VLOOKUP(B6,FG!$A$5:$H$1158,24,FALSE)) -> 0 | F6: =+SUM(D6:E6) -> #REF! | H6: 0 | I6: =+IF(F6<=0,"",IF(AND(F6>0,F6>H6),"NG","")) -> #REF! | J6: =IF(ISERROR(SUMIF(FG!A:A,LCM!B6,FG!#REF!)),0,SUMIF(FG!A:A,LCM!B6,FG!#REF!)) -> 0 | K6: =IF(I6="NG",(F6-H6)*J6,0) -> #REF!
B7: 030-06 | C7: 79040-0K010-E1 | D7: =VLOOKUP(B7,FG!$A$5:$H$1158,12,FALSE) -> #REF! | E7: =IF(J7<=0,0,VLOOKUP(B7,FG!$A$5:$H$1158,24,FALSE)) -> 0 | F7: =+SUM(D7:E7) -> #REF! | H7: 0 | I7: =+IF(F7<=0,"",IF(AND(F7>0,F7>H7),"NG","")) -> #REF! | J7: =IF(ISERROR(SUMIF(FG!A:A,LCM!B7,FG!#REF!)),0,SUMIF(FG!A:A,LCM!B7,FG!#REF!)) -> 0 | K7: =IF(I7="NG",(F7-H7)*J7,0) -> #REF!
B8: 030-07 | C8: 79030-0K010-E0 | D8: =VLOOKUP(B8,FG!$A$5:$H$1158,12,FALSE) -> #REF! | E8: =IF(J8<=0,0,VLOOKUP(B8,FG!$A$5:$H$1158,24,FALSE)) -> 0 | F8: =+SUM(D8:E8) -> #REF! | H8: 0 | I8: =+IF(F8<=0,"",IF(AND(F8>0,F8>H8),"NG","")) -> #REF! | J8: =IF(ISERROR(SUMIF(FG!A:A,LCM!B8,FG!#REF!)),0,SUMIF(FG!A:A,LCM!B8,FG!#REF!)) -> 0 | K8: =IF(I8="NG",(F8-H8)*J8,0) -> #REF!
B9: 030-08 | C9: 79040-0K010-E0 | D9: =VLOOKUP(B9,FG!$A$5:$H$1158,12,FALSE) -> #REF! | E9: =IF(J9<=0,0,VLOOKUP(B9,FG!$A$5:$H$1158,24,FALSE)) -> 0 | F9: =+SUM(D9:E9) -> #REF! | H9: 0 | I9: =+IF(F9<=0,"",IF(AND(F9>0,F9>H9),"NG","")) -> #REF! | J9: =IF(ISERROR(SUMIF(FG!A:A,LCM!B9,FG!#REF!)),0,SUMIF(FG!A:A,LCM!B9,FG!#REF!)) -> 0 | K9: =IF(I9="NG",(F9-H9)*J9,0) -> #REF!
B10: 150-13 | C10: 72503-X7A01 | D10: =VLOOKUP(B10,FG!$A$5:$H$1158,12,FALSE) -> #REF! | E10: =IF(J10<=0,0,VLOOKUP(B10,FG!$A$5:$H$1158,24,FALSE)) -> 0 | F10: =+SUM(D10:E10) -> #REF! | H10: 0 | I10: =+IF(F10<=0,"",IF(AND(F10>0,F10>H10),"NG","")) -> #REF! | J10: =IF(ISERROR(SUMIF(FG!A:A,LCM!B10,FG!#REF!)),0,SUMIF(FG!A:A,LCM!B10,FG!#REF!)) -> 0 | K10: =IF(I10="NG",(F10-H10)*J10,0) -> #REF!
B11: 150-14 | C11: 72504-X7A01 | D11: =VLOOKUP(B11,FG!$A$5:$H$1158,12,FALSE) -> #REF! | E11: =IF(J11<=0,0,VLOOKUP(B11,FG!$A$5:$H$1158,24,FALSE)) -> 0 | F11: =+SUM(D11:E11) -> #REF! | H11: 136.28 | I11: =+IF(F11<=0,"",IF(AND(F11>0,F11>H11),"NG","")) -> #REF! | J11: =IF(ISERROR(SUMIF(FG!A:A,LCM!B11,FG!#REF!)),0,SUMIF(FG!A:A,LCM!B11,FG!#REF!)) -> 0 | K11: =IF(I11="NG",(F11-H11)*J11,0) -> #REF!
B12: 150-15 | C12: 72503-X7A02 | D12: =VLOOKUP(B12,FG!$A$5:$H$1158,12,FALSE) -> #REF! | E12: =IF(J12<=0,0,VLOOKUP(B12,FG!$A$5:$H$1158,24,FALSE)) -> 0 | F12: =+SUM(D12:E12) -> #REF! | H12: 0 | I12: =+IF(F12<=0,"",IF(AND(F12>0,F12>H12),"NG","")) -> #REF! | J12: =IF(ISERROR(SUMIF(FG!A:A,LCM!B12,FG!#REF!)),0,SUMIF(FG!A:A,LCM!B12,FG!#REF!)) -> 0 | K12: =IF(I12="NG",(F12-H12)*J12,0) -> #REF!
B13: 150-16 | C13: 72504-X1F05 | D13: =VLOOKUP(B13,FG!$A$5:$H$1158,12,FALSE) -> #REF! | E13: =IF(J13<=0,0,VLOOKUP(B13,FG!$A$5:$H$1158,24,FALSE)) -> 0 | F13: =+SUM(D13:E13) -> #REF! | H13: 0 | I13: =+IF(F13<=0,"",IF(AND(F13>0,F13>H13),"NG","")) -> #REF! | J13: =IF(ISERROR(SUMIF(FG!A:A,LCM!B13,FG!#REF!)),0,SUMIF(FG!A:A,LCM!B13,FG!#REF!)) -> 0 | K13: =IF(I13="NG",(F13-H13)*J13,0) -> #REF!
B14: 152-01 | C14: 72503-X1F00 | D14: =VLOOKUP(B14,FG!$A$5:$H$1158,12,FALSE) -> #REF! | E14: =IF(J14<=0,0,VLOOKUP(B14,FG!$A$5:$H$1158,24,FALSE)) -> 0 | F14: =+SUM(D14:E14) -> #REF! | H14: 0 | I14: =+IF(F14<=0,"",IF(AND(F14>0,F14>H14),"NG","")) -> #REF! | J14: =IF(ISERROR(SUMIF(FG!A:A,LCM!B14,FG!#REF!)),0,SUMIF(FG!A:A,LCM!B14,FG!#REF!)) -> 0 | K14: =IF(I14="NG",(F14-H14)*J14,0) -> #REF!
B15: 152-02 | C15: 72504-X1F00 | D15: =VLOOKUP(B15,FG!$A$5:$H$1158,12,FALSE) -> #REF! | E15: =IF(J15<=0,0,VLOOKUP(B15,FG!$A$5:$H$1158,24,FALSE)) -> 0 | F15: =+SUM(D15:E15) -> #REF! | H15: 0 | I15: =+IF(F15<=0,"",IF(AND(F15>0,F15>H15),"NG","")) -> #REF! | J15: =IF(ISERROR(SUMIF(FG!A:A,LCM!B15,FG!#REF!)),0,SUMIF(FG!A:A,LCM!B15,FG!#REF!)) -> 0 | K15: =IF(I15="NG",(F15-H15)*J15,0) -> #REF!
B16: 152-03 | C16: 72503-X1F01 | D16: =VLOOKUP(B16,FG!$A$5:$H$1158,12,FALSE) -> #REF! | E16: =IF(J16<=0,0,VLOOKUP(B16,FG!$A$5:$H$1158,24,FALSE)) -> 0 | F16: =+SUM(D16:E16) -> #REF! | H16: 0 | I16: =+IF(F16<=0,"",IF(AND(F16>0,F16>H16),"NG","")) -> #REF! | J16: =IF(ISERROR(SUMIF(FG!A:A,LCM!B16,FG!#REF!)),0,SUMIF(FG!A:A,LCM!B16,FG!#REF!)) -> 0 | K16: =IF(I16="NG",(F16-H16)*J16,0) -> #REF!
B17: 152-04 | C17: 72504-X1F01 | D17: =VLOOKUP(B17,FG!$A$5:$H$1158,12,FALSE) -> #REF! | E17: =IF(J17<=0,0,VLOOKUP(B17,FG!$A$5:$H$1158,24,FALSE)) -> 0 | F17: =+SUM(D17:E17) -> #REF! | H17: 0 | I17: =+IF(F17<=0,"",IF(AND(F17>0,F17>H17),"NG","")) -> #REF! | J17: =IF(ISERROR(SUMIF(FG!A:A,LCM!B17,FG!#REF!)),0,SUMIF(FG!A:A,LCM!B17,FG!#REF!)) -> 0 | K17: =IF(I17="NG",(F17-H17)*J17,0) -> #REF!
... B1100: IFR-40 | C1100: 71103-X7V87 | D1100: =VLOOKUP(B1100,FG!$A$5:$H$1158,12,FALSE) -> #N/A | E1100: =IF(J1100<=0,0,VLOOKUP(B1100,FG!$A$5:$H$1158,24,FALSE)) -> 0 | F1100: =+SUM(D1100:E1100) -> #N/A | H1100: 322.85 | I1100: =+IF(F1100<=0,"",IF(AND(F1100>0,F1100>H1100),"NG","")) -> #N/A | J1100: =IF(ISERROR(SUMIF(FG!A:A,LCM!B1100,FG!#REF!)),0,SUMIF(FG!A:A,LCM!B1100,FG!#REF!)) -> 0 | K1100: =IF(I1100="NG",(F1100-H1100)*J1100,0) -> #N/A

Sheet BOM_FG
A1: Finish Goods(Part แม่) | C1: Raw Material(Part ลูก) | E1: Usage RM | F1: FG_Production | G1: RM_Used
A2: Finish Goods | B2: Parts_No. | C2: Back_No. | D2: Parts_No. | E2: Per Unit | F2: Q'ty | G2: Q'ty
A3: VD00-1 | B3: T05Z1B4100091 | C3: SAC008 | D3: U05B1S0720241 | E3: 1 | F3: 1 | G3: 1
A4: VD00-1 | B4: T05Z1B4100091 | C4: SAC007 | D4: U05B1S0720251 | E4: 1 | F4: 1 | G4: 1
A5: VD00-1 | B5: T05Z1B4100091 | C5: HYS048 | D5: U05B1S0720291 | E5: 1 | F5: 1 | G5: 1
A6: VD00-1 | B6: T05Z1B4100091 | C6: SAC006 | D6: U05B1S0720301 | E6: 1 | F6: 1 | G6: 1
A7: VD00-1 | B7: T05Z1B4100091 | C7: SNA005 | D7: U05Z1B4100301 | E7: 1 | F7: 1 | G7: 1
A8: VD00-1 | B8: T05Z1B4100091 | C8: SNA007 | D8: U05Z1B4100321 | E8: 1 | F8: 1 | G8: 1
A9: VD00-1 | B9: T05Z1B4100091 | C9: SNA008 | D9: U05Z1B4100331 | E9: 1 | F9: 1 | G9: 1
A10: VD00-1 | B10: T05Z1B4100091 | C10: SNA010 | D10: U05Z1B4100341 | E10: 1 | F10: 1 | G10: 1
A11: VD00-1 | B11: T05Z1B4100091 | C11: SNA011 | D11: U05Z1B4100351 | E11: 1 | F11: 1 | G11: 1
A12: VD00-1 | B12: T05Z1B4100091 | C12: SNA012 | D12: U05Z1B4100371 | E12: 1 | F12: 1 | G12: 1
A13: VD00-1 | B13: T05Z1B4100091 | C13: SNA013 | D13: U05Z1B4100421 | E13: 1 | F13: 1 | G13: 1
A14: VD00-1 | B14: T05Z1B4100091 | C14: ETT004 | D14: U05Z2B4100011 | E14: 1 | F14: 1 | G14: 1
... A319: TT8-12 | B319: 72120-X7V06 | C319: TTC770 | D319: 72205-X7V76 | E319: 1 | F319: 1 | G319: 1
A320: TT8-12 | B320: 72120-X7V06 | C320: TTC763 | D320: 72205-X7V50 | F320: 1 | G320: 0
A321: TT8-12 | B321: 72120-X7V06 | C321: KEN124 | D321: 72265-06040 | E321: 1 | F321: 1 | G321: 1
A322: TT8-12 | B322: 72120-X7V06 | C322: KEN120 | D322: 72284-X7V12 | E322: 2 | F322: 1 | G322: 2
A323: TT8-12 | B323: 72120-X7V06 | C323: KEN121 | D323: 72284-X7V13 | E323: 2 | F323: 1 | G323: 2
A324: TT8-12 | B324: 72120-X7V06 | C324: KEN122 | D324: 72284-X7V14 | E324: 2 | F324: 1 | G324: 2
A325: TT8-12 | B325: 72120-X7V06 | C325: KEN119 | D325: 72285-X7V04 | E325: 2 | F325: 1 | G325: 2
A326: TT8-12 | B326: 72120-X7V06 | C326: TFC017 | D326: 78157-X7V61 | E326: 0 | F326: 1 | G326: 0
A327: TT8-12 | B327: 72120-X7V06 | C327: TFC018 | D327: 78157-X7V62 | E327: 0 | F327: 1 | G327: 0
A328: TT8-12 | B328: 72120-X7V06 | C328: TFC019 | D328: 78157-X7V63 | E328: 0 | F328: 1 | G328: 0
A329: TT8-12 | B329: 72120-X7V06 | C329: TFC020 | D329: 78157-X7V64 | E329: 0 | F329: 1 | G329: 0
A330: TT8-12 | B330: 72120-X7V06 | C330: TFC021 | D330: 78157-X7V65 | E330: 0 | F330: 1 | G330: 0
A331: TT8-12 | B331: 72120-X7V06 | C331: TFC022 | D331: 78157-X7V66 | E331: 0 | F331: 1 | G331: 0
A332: TT8-12 | B332: 72120-X7V06 | C332: TFC023 | D332: 78157-X7V67 | E332: 0 | F332: 1 | G332: 0
... A364: TT8-10 | B364: 72130-X7V18 | C364: TTC771 | D364: 72205-X7V77 | E364: 1 | F364: 1 | G364: 1
A365: TT8-10 | B365: 72130-X7V18 | C365: TTC764 | D365: 72205-X7V51 | F365: 1 | G365: 0
A366: TT8-10 | B366: 72130-X7V18 | C366: TTC724 | D366: 72219-X7V03 | E366: 1 | F366: 1 | G366: 1
A367: TT8-10 | B367: 72130-X7V18 | C367: KEN124 | D367: 72265-06040 | E367: 1 | F367: 1 | G367: 1
A368: TT8-10 | B368: 72130-X7V18 | C368: TTC695 | D368: 72277-X7V01 | E368: 1 | F368: 1 | G368: 1
A369: TT8-10 | B369: 72130-X7V18 | C369: KEN120 | D369: 72284-X7V12 | E369: 2 | F369: 1 | G369: 2
A370: TT8-10 | B370: 72130-X7V18 | C370: KEN121 | D370: 72284-X7V13 | E370: 2 | F370: 1 | G370: 2
A371: TT8-10 | B371: 72130-X7V18 | C371: KEN122 | D371: 72284-X7V14 | E371: 2 | F371: 1 | G371: 2
A372: TT8-10 | B372: 72130-X7V18 | C372: KEN119 | D372: 72285-X7V04 | E372: 2 | F372: 1 | G372: 2
A373: TT8-10 | B373: 72130-X7V18 | C373: TFC017 | D373: 78157-X7V61 | E373: 0 | F373: 1 | G373: 0
A374: TT8-10 | B374: 72130-X7V18 | C374: TFC018 | D374: 78157-X7V62 | E374: 0 | F374: 1 | G374: 0
A375: TT8-10 | B375: 72130-X7V18 | C375: TFC019 | D375: 78157-X7V63 | E375: 0 | F375: 1 | G375: 0
...

Sheet BOM_Sub Assy
A1: Sub Assy(Part ลูก) | C1: Raw Material(Partหลาน) | E1: Usage RM | F1: WIP_Sub Assy | G1: RM_Used
A2: SD_No. | B2: Parts_No. | C2: Back_No. | D2: Parts_No. | E2: Per Unit | F2: Q'ty | G2: Q'ty
A3: AG9-01 | B3: 72505-X7A00 | C3: AP1-10 | D3: 72523-X7A00 | E3: 1 | F3: 1 | G3: 1
A4: AG9-01 | B4: 72505-X7A00 | C4: AOY003 | D4: 90174-T0004 | E4: 2 | F4: 1 | G4: 2
A5: AG9-02 | B5: 72505-X7A00 | C5: AP1-11 | D5: 72524-X7A00 | E5: 1 | F5: 1 | G5: 1
A6: AG9-02 | B6: 72505-X7A00 | C6: AOY003 | D6: 90174-T0004 | E6: 2 | F6: 1 | G6: 2
A7: AG9-03 | B7: 72507-X7A00 | C7: AP1-10 | D7: 72523-X7A00 | E7: 1 | F7: 1 | G7: 1
A8: AG9-03 | B8: 72507-X7A00 | C8: AOY003 | D8: 90174-T0004 | E8: 2 | F8: 1 | G8: 2
A9: AG9-03 | B9: 72507-X7A00 | C9: TTC506 | D9: 72548-X7A00 | E9: 1 | F9: 1 | G9: 1
A10: AG9-04 | B10: 72508-X7A00 | C10: AP1-11 | D10: 72524-X7A00 | E10: 1 | F10: 1 | G10: 1
A11: AG9-04 | B11: 72508-X7A00 | C11: AOY003 | D11: 90174-T0004 | E11: 2 | F11: 1 | G11: 2
A12: AG9-04 | B12: 72508-X7A00 | C12: TTC506 | D12: 72548-X7A00 | E12: 1 | F12: 1 | G12: 1
A13: AR0-01 | B13: 72510-X1M15-B | C13: HAN032 | D13: SPH27-14190 | E13: 0.105 | F13: 1 | G13: 0.105
A14: AR0-01 | B14: 72510-X1M15-B | C14: HAN033 | D14: SPH44-4388 | E14: 0.255 | F14: 1 | G14: 0.255
... A839: CTA-S7 | B839: - | C839: TTC672 | D839: 72226-X1405 | E839: 1 | F839: 1 | G839: 1
A840: EA-S1 | C840: SOB255 | D840: 72446-X1B00 | E840: 1 | F840: 1 | G840: 1
A841: EA-S1 | C841: MIT153 | D841: 72448-X1B01 | E841: 1 | F841: 1 | G841: 1
A842: EA-S1 | C842: OIL001 | D842: 72478-X1B02 | E842: 1 | F842: 1 | G842: 1
A843: EA-S2 | C843: SOB255 | D843: 72446-X1B00 | E843: 1 | F843: 1 | G843: 1
A844: EA-S2 | C844: MIT153 | D844: 72448-X1B01 | E844: 1 | F844: 1 | G844: 1
A845: EA-S2 | C845: OIL001 | D845: 72478-X1B02 | E845: 1 | F845: 1 | G845: 1
A846: EA-S3 | C846: MIT153 | D846: 72448-X1B01 | E846: 1 | F846: 1 | G846: 1
A847: EA-S3 | C847: MIY017 | D847: 72443-X7A03 | E847: 1 | F847: 1 | G847: 1
A848: EA-S3 | C848: OIL002 | D848: 72478-X1B03 | E848: 1 | F848: 1 | G848: 1
A849: EA-S4 | C849: MIT153 | D849: 72448-X1B01 | E849: 1 | F849: 1 | G849: 1
A850: EA-S4 | C850: MIY017 | D850: 72443-X7A03 | E850: 1 | F850: 1 | G850: 1
A851: EA-S4 | C851: OIL002 | D851: 72478-X1B03 | E851: 1 | F851: 1 | G851: 1
... A901: OT-S10 | C901: ETT001 | D901: 72468-X1B02 | E901: 2 | F901: 1 | G901: 2
A902: OT-S1 | B902: 72101-X1711 | C902: MIT170 | D902: 72149-X1V09 | E902: 1 | F902: 1 | G902: 1
A903: OT-S1 | B903: 72101-X1711 | C903: OTP-03 | D903: 72141-X1704 | E903: 1 | F903: 1 | G903: 1
A904: OT-S2 | B904: 72101-X1713 | C904: MIT170 | D904: 72149-X1V09 | E904: 1 | F904: 1 | G904: 1
A905: OT-S2 | B905: 72101-X1713 | C905: OTP-04 | D905: 72142-X1705 | E905: 1 | F905: 1 | G905: 1
A906: OT-S3 | B906: 72102-X1709 | C906: MIT170 | D906: 72149-X1V09 | E906: 1 | F906: 1 | G906: 1
A907: OT-S3 | B907: 72102-X1709 | C907: OTP-01 | D907: 72145-X1706 | E907: 1 | F907: 1 | G907: 1
A908: OT-S4 | B908: 72102-X1710 | C908: MIT170 | D908: 72149-X1V09 | E908: 1 | F908: 1 | G908: 1
A909: OT-S4 | B909: 72102-X1710 | C909: OTP-02 | D909: 72146-X1704 | E909: 1 | F909: 1 | G909: 1
A910: A8S01-I | B910: A8S01-IMV | C910: SOB254 | D910: 72441-X1C02 | E910: 1 | F910: 1 | G910: 1
A911: A8S01-I | B911: A8S01-IMV | C911: MIT158 | D911: 72469-X1C00 | E911: 1 | F911: 1 | G911: 1
A912: A8S01-I | B912: A8S01-IMV | C912: MIT159 | D912: 72469-X1C01 | E912: 1 | F912: 1 | G912: 1
A913: A8S01-I | B913: A8S01-IMV | C913: SOB253 | D913: 72441-X1C01 | E913: 1 | F913: 1 | G913: 1
...

Sheet RM
A2: Back_No. | B2: Parts_No. | C2: Parts_Name | D2: Q'ty/Box | E2: Project | F2: Cost/Unit
A4: AR0-01 | B4: 72510-X1M15 | C4: ADJUSTER ASSY FR SEAT RECLINING RH (TBSM) | D4: 36 | E4: REC | F4: 0
A5: AR0-02 | B5: 72520-X1M16 | C5: ADJUSTER ASSY FR SEAT RECLINING LH (TBSM) | D5: 36 | E5: REC | F5: 0
A6: N32-02 | B6: 72531-X1C02 | C6: Ratchet | D6: 0 | E6: REC | F6: 10.391543
A7: N32-18 | B7: 72523-X1M06 | C7: PLATE, RECLINING ADJUSTER LWR ARM, RH (GUIDE) | D7: 0 | E7: REC | F7: 7.9020977
A8: TGL-02 | B8: 72520-X7V26-P | F8: 0
A9: TGR-01 | B9: 72510-X7V45-P | F9: 0
A10: GB0-02 | B10: 72211-0K050-ED | C10: HANDLE SEAT TRACK ADJUSTING | D10: 20 | E10: IMV | F10: 30.25
A11: THT-33 | B11: 72211-06150-ED | C11: HANDLE SEAT TRACK ADJUSTING | D11: 8 | E11: TNGA | F11: 25.68
A12: HYS012 | B12: 72638-X1705 | C12: SPRING, RR SEAT BACK LOCK,LH | D12: 140 | F12: 17.06
A13: SOB310 | B13: 79133-X1702 | C13: LEG,NO.1 SEAT,INNER RH | D13: 12 | E13: New Camry | F13: 74.672
A14: TTC703 | B14: 72402-X7V32 | C14: HOUSING SUB-ASSY, FR SEAT MOTOR SIDE, LH | E14: TBK4 | F14: 331.52528
A15: KEN132 | B15: 72125-0D120 | C15: COVER, SEAT TRACK, UPR RR | E15: 535B | F15: 0.84
A16: KEN135 | B16: 72265-BZ060 | F16: 0.99
A17: DHT-72 | B17: 72211-BZ180-ED | C17: HANDLE, SEAT TRACK ADJUSTING (R3) | D17: 12 | E17: D92A | F17: 73.54
A18: CFS-40 | B18: 71111-X1B01 | C18: FRAME, FR SEAT CUSHION | D18: 10 | E18: New Camry | F18: 30.17981
A19: IPA-82 | B19: 72521-X7A04-P | C19: ARM, RECLINING ADJUSTER, LWR RH | D19: 12 | E19: 578W | F19: 41.67465
A20: IPF-66 | B20: 71151-X7V03-P | C20: FRAME, FR SEAT BACK, RH | D20: 15 | E20: 578W | F20: 28.700603
A21: DPT-05 | B21: 72115-X7V45-P | F21: 22.606301
A22: N32-05 | B22: 72537-X1F00-P | C22: CAM | D22: 250 | E22: REC | F22: 2.6881233
A23: CP2-02 | B23: 72161-X7A04 | C23: RAIL RR SEAT TRACK UPR | D23: 20 | E23: IMV | F23: 26.724653
A24: IPA-81 | B24: 72522-X7A04-P | C24: ARM, RECLINING ADJUSTER, LWR OUTER LH | D24: 12 | E24: 578W | F24: 41.718316
A25: IPT-87 | B25: 72141-X7A05-P | C25: BRACKET, FR OUTER SEAT TRACK, LWR FR RH | D25: 40 | E25: 578W | F25: 11.290288
A26: MIT150 | B26: 72745-X7A03 | C26: PIN RECLINING HINGE | D26: 300 | E26: SK4G | F26: 5.8693522
A27: SOJ602 | B27: GREAS-MA021 | C27: GREASE MULTEMP TA NO1 (15 Kg.) | D27: 1 | E27: SK4G | F27: 196.39145
A28: SOB308 | B28: 79131-X1701 | C28: LEG,NO.1 SEAT,RH | D28: 10 | E28: New Camry | F28: 57.505238
A29: SOB309 | B29: 79132-X1701 | C29: LEG,NO.1 SEAT,LH | D29: 10 | E29: New Camry | F29: 57.495747
A30: SOB311 | B30: 79134-X1702 | C30: LEG,NO.1 SEAT,INNER LH | D30: 12 | E30: New Camry | F30: 74.661644
A31: CTP-27 | B31: 72115-X1403 | C31: RAIL, SEAT TRACK, LWR | D31: 20 | E31: New Camry | F31: 22.6669
A32: IPT-90 | B32: 72147-X7A05-P | C32: BRACKET, FR INNER SEAT TRACK, LWR RR RH | D32: 50 | E32: 578W | F32: 13.7195
A33: IPF-65 | B33: 71152-X7V03-P | C33: FRAME, FR SEAT BACK, LH | D33: 15 | E33: 578W | F33: 28.71099
A34: BTS127 | B34: 73192-X7V16 | C34: BRACKET, SEAT BELT INNER ANCHOR, LH | E34: TNGA | F34: 23.36
A35: MIY048 | B35: 73192-X7A11 | C35: BRACKET, SEAT BELT INNER ANCHOR, LH | E35: 716B | F35: 0
A36: EPA-48 | B36: 72521-X7V47-P | C36: ARM, RECLINING ADJUSTER LWR RH(M4) | E36: 535B | F36: 37.584796
A37: IPT-08 | B37: 72115-X7V40-P | F37: 25.216798
A38: DPT-08 | B38: 72111-X7V19-P | F38: 22.280285
A39: BWT003 | B39: AWSDM-KRC28 | C39: Kiswel-KC-28 AWS:ER70S-6 1.0 MM (300Kg P/Pack) | F39: 54.5
A40: CTP-28 | B40: 72114-X1405 | C40: RAIL, SEAT TRACK, UPR LH | D40: 30 | E40: New Camry | F40: 20.522439
A41: DPA-02 | B41: 72521-X7V74-P | F41: 39.454575
A42: EHT-13 | B42: 72211-0D160-ED | C42: HANDLE SEAT TRACK ADJUSTING | D42: 24 | E42: TBK4 | F42: 32.13
...

Sheet FG
A1: Finish Goods :
A3: Back_no | B3: Part No. | C3: Part Name | D3: Q'ty/Box | E3: Project | F3: Model | G3: BOI | H3: Cost/Unit
A5: OA6-28 | B5: 72503-X1717 | C5: ARM SUB-ASSY, RECLINING ADJUSTER, RH | D5: 8 | E5: SK4G | F5: New Camry | G5: BOI-P.3 | H5: 0
A6: TGP-02 | B6: 72524-X7V44 | E6: Next IMV | G6: NON BOI | H6: 5.25
A7: MIT162 | B7: 72519-X1K04 | C7: PIN, RECLINING HINGE | D7: 400 | E7: SK4G | F7: New Camry | G7: NON BOI | H7: 4.76
A8: SOB309 | B8: 79132-X1701 | C8: LEG, NO.1 SEAT, LH | D8: 10 | E8: SK4G | F8: New Camry | G8: NON BOI | H8: 57.5
A9: SOB311 | B9: 79134-X1702 | C9: LEG, NO.1 SEAT, INNER LH | D9: 12 | E9: SK4G | F9: New Camry | G9: NON BOI | H9: 74.66
A10: MIT188 | B10: 72745-X7A08 | C10: PIN, RR SEAT RECLINING HINGE | D10: 150 | E10: Next IMV | G10: NON BOI | H10: 10.84
A11: HYS043 | B11: 89953-X7029 | C11: SPRING, SPIRAL | D11: 120 | E11: Next IMV | G11: NON BOI | H11: 13.99
A12: MIT199 | B12: 72559-X7A01 | C12: PIN, SPRING SET | D12: 100 | E12: Next IMV | G12: NON BOI | H12: 23.29
A13: BTS160 | B13: 72426-X1406 | E13: TNGA | G13: BOI-P.2 | H13: 3.13
A14: BTS140 | B14: 72781-X7V03 | E14: TNGA | G14: NON BOI | H14: 11.22
A15: MIT238 | B15: 89911-X7127 | C15: BOLT, WELD | E15: DG7 | G15: NON BOI | H15: 5.26
A16: BTS078 | B16: 73214-0K010 | C16: PLATE FR SEAT BELT ANCHOR | D16: 4000 | E16: SK4G | F16: New Camry | G16: NON BOI | H16: 2.64
A17: OIL001 | B17: 72478-X1B02 | C17: BUSH, VERTICAL ADJUSTER | D17: 3000 | E17: SK4G | F17: New Camry | G17: NON BOI | H17: 2.1
A18: SOB322 | B18: 72579-X1700 | C18: PLATE, SPRING SET | D18: 200 | E18: SK4G | F18: New Camry | G18: NON BOI | H18: 6.06
A19: IFL-07 | B19: 71104-X7A00 | C19: FRAME SUB-ASSY, FR SEAT BACK MAIN, LH | D19: 8 | E19: Next IMV | G19: BOI-P.5 | H19: 129.0194
A20: IFR-74 | B20: 71103-X7A16 | C20: FRAME SUB-ASSY, FR SEAT BACK MAIN, RH | D20: 4 | E20: Next IMV | G20: BOI-P.5 | H20: 136.64829
A21: STM-03 | B21: 11213-0E010 | C21: GASKET, CYLINDER HEAD COVER (11213-X7A00) | D21: 1 | E21: CHC | G21: BOI-P.4 | H21: 64.71
A22: MIT183 | B22: 71311-X7A00 | C22: PIN, FR SEAT HINGE | D22: 200 | E22: Next IMV | G22: NON BOI | H22: 23.84
A23: MIT184 | B23: 72519-X7A12 | C23: PIN, RECLINING HINGE | D23: 100 | E23: Next IMV | G23: NON BOI | H23: 22.83
A24: HYS046 | B24: 89953-X7041 | C24: SPRING, SPIRAL | D24: 72 | E24: Next IMV | G24: NON BOI | H24: 24.41
A25: TA6-17 | B25: 73042-X7V20 | C25: ADJUSTER SUB-ASSY, FR SEAT, INNER LH | E25: TNGA | G25: BOI-P.5 | H25: 157.12118
A26: IA4-81 | B26: 72504-X7A22 | C26: ARM SUB-ASSY, RECLINING ADJUSTER, LH | E26: Next IMV | G26: BOI-P.5 | H26: 45.54
A27: HRC-24 | B27: 79304-X1E05 | C27: FRAME SUB-ASSY, NO.3 SEAT BACK, LH | E27: 181B | G27: NON BOI | H27: 0
A28: BTS156 | B28: 72446-X7V34 | C28: LINK, VERTICAL TRAVEL, NO.4 | E28: TNGA | G28: NON BOI | H28: 38.72
A29: MIY051 | B29: 72443-X7V76 | C29: GEAR, VERTICAL ADJUSTER | E29: TNGA | G29: NON BOI | H29: 62.95641
A30: HYS059 | B30: 89953-X7062 | E30: Next IMV | F30: 867B | G30: NON BOI | H30: 21.57
A31: ITO-96 | B31: 72110-X7V65 | E31: Next IMV | F31: 867B | G31: NON BOI | H31: 164.35284
A32: LT8-81 | B32: 721C0-X7V62 | C32: TRACK ASSY, FR SEAT, INNER RH | E32: Next IMV | F32: 500D | G32: NON BOI | H32: 245.555
A33: LT8-82 | B33: 721A0-X7V38 | C33: TRACK ASSY, FR SEAT, OUTER RH | E33: Next IMV | F33: 500D | G33: NON BOI | H33: 227.40788
A34: OTO-40 | B34: 72116-X1701 | C34: RAIL, FR OUTER SEAT TRACK, LWR LH | D34: 8 | E34: SK4G | F34: New Camry | G34: NON BOI | H34: 54.48
A35: ETO-11 | B35: 72110-X1V15 | C35: TRACK ASSY, FR SEAT, OUTER RH | D35: 4 | E35: EFC | F35: EFC | G35: BOI-P.3 | H35: 151.72
A36: TA8-24 | B36: 73032-X7V21 | C36: ADJUSTER SUB-ASSY, FR SEAT, OUTER LH | E36: TNGA | G36: BOI-P.5 | H36: 229.73274
A37: DPF-70 | B37: 79151-X7V09 | C37: FRAME, NO.1 SEAT BACK | E37: DG7 | F37: D92A | G37: BOI-P.3 | H37: 18.978451
A38: CFS-59 | B38: 71152-X1V05 | C38: FRAME, FR SEAT BACK, LH | D38: 12 | E38: EFC | F38: EFC | G38: BOI-P.2 | H38: 32.89
A39: CFP-10 | B39: 72524-X1408 | C39: PLATE, RECLINING ADJUSTER LWR ARM, RH (MNL) | D39: 50 | E39: SK4G | F39: New Camry | G39: BOI-P.3 | H39: 11.21
A40: CTP-28 | B40: 72114-X1405 | C40: RAIL, SEAT TRACK, UPR RH/LH | D40: 24 | E40: SK4G | F40: New Camry | G40: NON BOI | H40: 20.78
A41: SOB310 | B41: 79133-X1702 | C41: LEG, NO.1 SEAT, INNER RH | D41: 12 | E41: SK4G | F41: New Camry | G41: NON BOI | H41: 74.67
A42: AP1-03 | B42: 71254-X7A01 | C42: FRAME, RR SEAT BACK SIDE, RH | D42: 20 | E42: IMV | G42: NON BOI | H42: 23.28
...

Sheet Press
A1: back_no | B1: parts_no | C1: rec_qtyの合計
A2: AP1-03 | B2: 71254-X7A01-P | C2: 22140
A3: AP1-04 | B3: 71255-X7A01-P | C3: 23680
A4: AP1-12 | B4: 72521-X7A02-P | C4: 5400
A5: AP1-13 | B5: 72522-X7A02-P | C5: 3600
A6: AR0-01 | B6: 72510-X1M15 | C6: 100584
A7: AR0-02 | B7: 72520-X1M16 | C7: 105876
A8: CAP-01 | B8: 71111-X1C00-P | C8: 15720
A9: CAP-02 | B9: 71112-X1C00-P | C9: 14100
A10: CAP-05 | B10: 72521-X1B05-P | C10: 16260
A11: CAP-06 | B11: 72522-X1B02-P | C11: 19720
A12: CAP-07 | B12: 72521-X1C03-P | C12: 21000
A13: CAP-08 | B13: 72522-X1C02-P | C13: 22140
... A259: ZST002 | B259: ZFS240-30008 | C259: -9000
C260: 2526263
C263: #REF!
B266: Round Reclining - Press | C266: #REF!
B268: Diff. | C268: #REF!
A272: 72510-X1M15 | B272: ADJUSTER ASSY, FR SEAT RECLINING, RH (EXP)
A273: 72520-X1M16 | B273: ADJUSTER ASSY, FR SEAT RECLINING, LH (EXP)
A274: 72520-X7V26
A275: 72510-X7V45

Sheet WIP
A4: Work In Process :
A6: Back_No. | B6: Parts_No. | C6: Parts_Name | D6: Category | E6: Work In Process | G6: Cost/Unit | H6: Process Cost
E7: Q'ty | F7: Amount (THB) | H7: Per Unit | I7: Amount (THB)
A8: 030-05 | B8: 79030-0K010-E1 | C8: LEG ASSY RR NO2 RH | D8: FG | E8: 0 | F8: 0 | G8: 0 | H8: 4.96 | I8: 0
A9: 030-06 | B9: 79040-0K010-E1 | C9: LEG ASSY RR NO2 LH | D9: FG | E9: 0 | F9: 0 | G9: 0 | H9: 4.96 | I9: 0
A10: 030-07 | B10: 79030-0K010-E0 | C10: LEG ASSY RR NO2 RH | D10: FG | E10: 0 | F10: 0 | G10: 0 | H10: 4.96 | I10: 0
A11: 030-08 | B11: 79040-0K010-E0 | C11: LEG ASSY RR NO2 LH | D11: FG | E11: 0 | F11: 0 | G11: 0 | H11: 4.96 | I11: 0
A12: 150-13 | B12: 72503-X7A01 | C12: ARM SUB-ASSY, RECLINING ADJUSTER, LWR RH | D12: FG | E12: 0 | F12: 0 | G12: 0 | H12: 0.85 | I12: 0
A13: 150-14 | B13: 72504-X1410 | C13: ARM SUB-ASSY, RECLINING ADJUSTER, LWR LH | D13: FG | E13: 0 | F13: 0 | G13: 0 | H13: 0.85 | I13: 0
A14: 150-15 | B14: 72503-X7A02 | C14: ARM SUB-ASSY, RECLINING ADJUSTER, LWR RH | D14: FG | E14: 0 | F14: 0 | G14: 0 | H14: 0.85 | I14: 0
A15: 150-16 | B15: 72504-X1F05 | C15: ARM SUB-ASSY, RECLINING ADJUSTER, LWR LH | D15: FG | E15: 0 | F15: 0 | G15: 0 | H15: 0.85 | I15: 0
A16: 152-01 | B16: 72503-X1F00 | C16: ARM SUB-ASSY, RECLINING ADJUSTER, LWR RH | D16: FG | E16: 0 | F16: 0 | G16: 0 | H16: 0.85 | I16: 0
A17: 152-02 | B17: 72504-X1F00 | C17: ARM SUB-ASSY, RECLINING ADJUSTER, LWR LH | D17: FG | E17: 0 | F17: 0 | G17: 0 | H17: 0.85 | I17: 0
A18: 152-03 | B18: 72503-X1F01 | C18: ARM SUB-ASSY, RECLINING ADJUSTER, LWR RH | D18: FG | E18: 0 | F18: 0 | G18: 0 | H18: 0.85 | I18: 0
A19: 152-04 | B19: 72504-X1F01 | C19: ARM SUB-ASSY, RECLINING ADJUSTER, LWR LH | D19: FG | E19: 0 | F19: 0 | G19: 0 | H19: 0.85 | I19: 0
... A346: EHT-13 | B346: 72211-0D160 | C346: HANDLE, SEAT TRACK ADJUSTING | D346: FG | E346: 0 | F346: 0 | G346: 20.69 | H346: 56.35 | I346: 0
A347: CFL-57 | D347: FG | E347: 0 | F347: 0 | G347: 0 | H347: 0 | I347: 0
A348: IFL-17 | D348: FG | E348: 0 | F348: 0 | G348: 141.11 | H348: 21 | I348: 0
A349: IFR-14 | D349: FG | E349: 0 | F349: 0 | G349: 113.67 | H349: 38.59 | I349: 0
A350: IFR-18 | D350: FG | E350: 0 | F350: 0 | G350: 141.24 | H350: 28.11 | I350: 0
A351: ITI-27 | D351: FG | E351: 0 | F351: 0 | G351: 197.55 | H351: 97.04 | I351: 0
A352: ITI-29 | D352: FG | E352: 0 | F352: 0 | G352: 197.14 | H352: 97.04 | I352: 0
A353: ITO-20 | D353: FG | E353: 3 | F353: 399.96 | G353: 128.83 | H353: 101.6 | I353: 304.8
A354: ITO-22 | D354: FG | E354: 0 | F354: 0 | G354: 129.87 | H354: 101.6 | I354: 0
A355: ITO-28 | D355: FG | E355: 0 | F355: 0 | G355: 198.13 | H355: 97.04 | I355: 0
A356: ITO-30 | D356: FG | E356: 0 | F356: 0 | G356: 198.36 | H356: 97.04 | I356: 0
A357: OA4-63 | D357: FG | E357: 0 | F357: 0 | G357: 0 | H357: 316.26 | I357: 0
A358: OTI-37 | D358: FG | E358: 0 | F358: 0 | G358: 64.66 | H358: 16.58 | I358: 0
... A362: THT-33 | D362: FG | E362: 0 | F362: 0 | G362: 14.76 | H362: 12.02 | I362: 0
A363: AOY001 | B363: 72641-0K020 | C363: RIVET | D363: Parts | E363: 0 | F363: 0 | G363: 0 | H363: #REF! | I363: #REF!
A364: AOY002 | B364: 90174-T0003 | C364: NUT WELD | D364: Parts | E364: 1940 | F364: 1610.2 | G364: 0.83 | H364: #REF! | I364: #REF!
A365: AOY003 | B365: 90174-T0004 | C365: NUT WELD | D365: Parts | E365: 526 | F365: 657.5 | G365: 1.25 | H365: #REF! | I365: #REF!
A366: AOY004 | B366: 90174-08039 | C366: NUT WELD | D366: Parts | E366: 0 | F366: 0 | G366: 0 | H366: #REF! | I366: #REF!
A367: AOY005 | B367: 72702-X1413 | C367: BOLT | D367: Parts | E367: 749 | F367: 1400.63 | G367: 1.87 | H367: #REF! | I367: #REF!
A368: AOY006 | B368: 94151-80800 | C368: NUT, FLANGE | D368: Parts | E368: 3252 | F368: 3121.92 | G368: 0.96 | H368: #REF! | I368: #REF!
A369: BTS010 | B369: 71897-X7A01 | C369: HOOK SEAT COVER SIDE | D369: Parts | E369: 36 | F369: 129.6 | G369: 3.6 | H369: #REF! | I369: #REF!
A370: BTS011 | B370: 72558-X7A00 | C370: STOPPER RECLINING | D370: Parts | E370: 87 | F370: 427.17 | G370: 4.91 | H370: #REF! | I370: #REF!
A371: BTS012 | B371: 72558-X7A01 | C371: STOPPER RECLINING | D371: Parts | E371: 0 | F371: 0 | G371: 0 | H371: #REF! | I371: #REF!
A372: BTS013 | B372: 72777-X7A00 | C372: PLATE RR SEAT RECLINING BRACKET | D372: Parts | E372: 0 | F372: 0 | G372: 4 | H372: #REF! | I372: #REF!
A373: BTS014 | B373: 72777-X7A01 | C373: PLATE RR SEAT RECLINING BRACKET | D373: Parts | E373: 0 | F373: 0 | G373: 0 | H373: #REF! | I373: #REF!
...

Sheet YDT_Mar.11
B2: YARNAPUND DAISO (THAILAND) CO., LTD.
B4: 700/507 Moo. 2 T. Bannkao A. Phanthong Chonburi 20160
D6: Tel. : 038-454717-9 | F6: Fax. : 038-454721
A8: ATTN : K. TIK ,Veerasak ( TBSM ) | E8: FAX NO. : 038-210-018
A9: FROM : K. CHAIROT ( YDT )
A11: STOCK CARD TBSM.
A12: On 31 MAR 2011
A15: ITEM | B15: PART CODE | C15: PART NO. | D15: PART NAME | E15: PACKING (pcs.) | F15: SAFETY STOCK YDT (pcs.) | H15: PART RECEIVE 30-12-10 | J15: TOTAL STOCK
F16: Boxes | G16: Pcs | H16: Boxes | I16: Pcs | J16: Boxes | K16: Pcs
A17: 1 | B17: YDT-001 | C17: 72516-X1400-00-F | D17: ARM RECLINING ADJUSTER RELEASE LH | E17: 100 | F17: =+G17/E17 -> 0 | G17: 0 | H17: 4 | I17: =H17*100 -> 400 | J17: =F17+H17 -> 4 | K17: =G17+I17 -> 400
A18: 2 | B18: YDT-002 | C18: 72515-X1400-00-F | D18: ARM RECLINING ADJUSTER RELEASE RH | E18: 100 | F18: =+G18/E18 -> 0 | G18: 0 | H18: 4 | I18: =H18*100 -> 400 | J18: =F18+H18 -> 4 | K18: =G18+I18 -> 400
A19: 3 | B19: YDT-007 | C19: 72515-X1F02-00-D | D19: ARM RECLINING ADJUSTER RELEASE RH | E19: 100 | F19: =+G19/E19 -> 10 | G19: 1000 | H19: 11 | I19: =H19*100 -> 1100 | J19: =F19+H19 -> 21 | K19: =G19+I19 -> 2100
A20: 4 | B20: YDT-008 | C20: 72516-X1F02-00-D | D20: ARM RECLINING ADJUSTER RELEASE LH | E20: 100 | F20: =+G20/E20 -> 10 | G20: 1000 | H20: 9 | I20: =H20*100 -> 900 | J20: =F20+H20 -> 19 | K20: =G20+I20 -> 1900
C24: YARNAPUND DAISO(THAILAND)CO.,LTD | E24: TOYOTA BOSHOKU SIAM METAL(THAILAND)CO.,LTD
B26: Chairot P.
B28: Date. | C28: 31/03/2011 | E28: Date.

Sheet YDT_Feb.11
B2: YARNAPUND DAISO (THAILAND) CO., LTD.
B4: 700/507 Moo. 2 T. Bannkao A. Phanthong Chonburi 20160
D6: Tel. : 038-454717-9 | F6: Fax. : 038-454721
A8: ATTN : K. TIK ,Veerasak ( TBSM ) | E8: FAX NO. : 038-210-018
A9: FROM : K. CHAIROT ( YDT )
A11: STOCK CARD TBSM.
A12: On 28 FEB 2011
A15: ITEM | B15: PART CODE | C15: PART NO. | D15: PART NAME | E15: PACKING (pcs.) | F15: SAFETY STOCK YDT (pcs.) | H15: PART RECEIVE 30-12-10 | J15: TOTAL STOCK
F16: Boxes | G16: Pcs | H16: Boxes | I16: Pcs | J16: Boxes | K16: Pcs
A17: 1 | B17: YDT-001 | C17: 72516-X1400-00-F | D17: ARM RECLINING ADJUSTER RELEASE LH | E17: 100 | F17: =+G17/E17 -> 0 | G17: 0 | H17: 2 | I17: =H17*100 -> 200 | J17: =F17+H17 -> 2 | K17: =G17+I17 -> 200
A18: 2 | B18: YDT-002 | C18: 72515-X1400-00-F | D18: ARM RECLINING ADJUSTER RELEASE RH | E18: 100 | F18: =+G18/E18 -> 0 | G18: 0 | H18: 3 | I18: =H18*100 -> 300 | J18: =F18+H18 -> 3 | K18: =G18+I18 -> 300
A19: 3 | B19: YDT-007 | C19: 72515-X1F02-00-D | D19: ARM RECLINING ADJUSTER RELEASE RH | E19: 100 | F19: =+G19/E19 -> 10 | G19: 1000 | H19: 9 | I19: =H19*100 -> 900 | J19: =F19+H19 -> 19 | K19: =G19+I19 -> 1900
A20: 4 | B20: YDT-008 | C20: 72516-X1F02-00-D | D20: ARM RECLINING ADJUSTER RELEASE LH | E20: 100 | F20: =+G20/E20 -> 10 | G20: 1000 | H20: 9 | I20: =H20*100 -> 900 | J20: =F20+H20 -> 19 | K20: =G20+I20 -> 1900
C24: YARNAPUND DAISO(THAILAND)CO.,LTD | E24: TOYOTA BOSHOKU SIAM METAL(THAILAND)CO.,LTD
B26: Chairot P.
B28: Date. | C28: 28/02/2011 | E28: Date.

Sheet YDT_Mar.10
B2: YARNAPUND DAISO (THAILAND) CO., LTD.
B4: 700/507 Moo. 2 T. Bannkao A. Phanthong Chonburi 20160
D6: Tel. : 038-454717-9 | F6: Fax. : 038-454721
A9: TO. : K. TIK (ARST) | D9: FAX NO. : 038-210-018
A11: FROM : K. PAYAB (YDT)
A14: STOCK CARD ARST.
A15: On 31 March 2010
A18: ITEM | B18: PART CODE | C18: PART NO. | D18: PART NAME | E18: PACKING (pcs.) | F18: SAFETY STOCK YDT (pcs.) | G18: PART RECEIVE 31-3-10 (pcs.) | H18: TOTAL (box) | I18: TOTAL (pcs.)
A19: 1 | B19: YDT-001 | C19: 72516-X1400-00-F | D19: ARM RECLINING ADJUSTER RELEASE LH | E19: 100 | F19: 0 | G19: 200 | H19: 2 | I19: 200
A20: 2 | B20: YDT-002 | C20: 72515-X1400-00-F | D20: ARM RECLINING ADJUSTER RELEASE RH | E20: 100 | F20: 0 | G20: 100 | H20: 1 | I20: 100
A21: 3 | B21: YDT-007 | C21: 72515-X1F02-00-D | D21: ARM RECLINING ADJUSTER RELEASE RH | E21: 100 | F21: 1000 | G21: 600 | H21: 16 | I21: 1600
A22: 4 | B22: YDT-008 | C22: 72516-X1F02-00-D | D22: ARM RECLINING ADJUSTER RELEASE LH | E22: 100 | F22: 1000 | G22: 600 | H22: 16 | I22: 1600
B26: Yarnapund Daiso ( Thailand ) Co., Ltd. | E26: ARST. ( Thailand ) Co., Ltd.
B33: Date. | E33: Date.

Sheet YDT_Apr.10
B2: YARNAPUND DAISO (THAILAND) CO., LTD.
B4: 700/507 Moo. 2 T. Bannkao A. Phanthong Chonburi 20160
D6: Tel. : 038-454717-9 | F6: Fax. : 038-454721
A9: TO. : K. TIK ,Veerasak ( TBSM ) | D9: FAX NO. : 038-210-018
A11: FROM : K. PAYAB ( YDT )
A14: STOCK CARD TBSM.
A15: On 30 April 2010
A18: ITEM | B18: PART CODE | C18: PART NO. | D18: PART NAME | E18: PACKING (pcs.) | F18: SAFETY STOCK YDT (pcs.) | G18: PART RECEIVE 30-4-10 (pcs.) | H18: TOTAL (box) | I18: TOTAL (pcs.)
A19: 1 | B19: YDT-001 | C19: 72516-X1400-00-F | D19: ARM RECLINING ADJUSTER RELEASE LH | E19: 100 | F19: 0 | G19: 200 | H19: 2 | I19: 200
A20: 2 | B20: YDT-002 | C20: 72515-X1400-00-F | D20: ARM RECLINING ADJUSTER RELEASE RH | E20: 100 | F20: 0 | G20: 100 | H20: 1 | I20: 100
A21: 3 | B21: YDT-007 | C21: 72515-X1F02-00-D | D21: ARM RECLINING ADJUSTER RELEASE RH | E21: 100 | F21: 1000 | G21: 700 | H21: 17 | I21: 1700
A22: 4 | B22: YDT-008 | C22: 72516-X1F02-00-D | D22: ARM RECLINING ADJUSTER RELEASE LH | E22: 100 | F22: 1000 | G22: 700 | H22: 17 | I22: 1700
B26: Yarnapund Daiso ( Thailand ) Co., Ltd. | E26: Toyota Boshoku Siam Metal ( Thailand ) Co., Ltd.
B33: Date. | E33: Date.

Sheet YDT_May.10
B2: YARNAPUND DAISO (THAILAND) CO., LTD.
B4: 700/507 Moo. 2 T. Bannkao A. Phanthong Chonburi 20160
D6: Tel. : 038-454717-9 | G6: Fax. : 038-454721
A9: TO. : K. TIK ,Veerasak ( TBSM ) | D9: FAX NO. : 038-210-018
A11: FROM : K. PAYAB ( YDT )
A14: STOCK CARD TBSM.
A15: On 31 MAY 2010
A18: ITEM | B18: PART CODE | C18: PART NO. | D18: PART NAME | E18: PACKING (pcs.) | F18: SAFETY STOCK YDT (pcs.) | H18: PART RECEIVE 31-5-10 | J18: TOTAL STOCK
F19: Boxes | G19: Pcs | H19: Boxes | I19: Pcs | J19: Boxes | K19: Pcs
A20: 1 | B20: YDT-001 | C20: 72516-X1400-00-F | D20: ARM RECLINING ADJUSTER RELEASE LH | E20: 100 | F20: =+G20/E20 -> 0 | G20: 0 | H20: 0 | J20: 0 | K20: =+H20+G20 -> 0
A21: 2 | B21: YDT-002 | C21: 72515-X1400-00-F | D21: ARM RECLINING ADJUSTER RELEASE RH | E21: 100 | F21: =+G21/E21 -> 0 | G21: 0 | H21: 0 | J21: 0 | K21: =+H21+G21 -> 0
A22: 3 | B22: YDT-007 | C22: 72515-X1F02-00-D | D22: ARM RECLINING ADJUSTER RELEASE RH | E22: 100 | F22: =+G22/E22 -> 10 | G22: 1000 | H22: 0 | J22: 0 | K22: =+H22+G22 -> 1000
A23: 4 | B23: YDT-008 | C23: 72516-X1F02-00-D | D23: ARM RECLINING ADJUSTER RELEASE LH | E23: 100 | F23: =+G23/E23 -> 10 | G23: 1000 | H23: 0 | J23: 0 | K23: =+H23+G23 -> 1000
B27: Yarnapund Daiso ( Thailand ) Co., Ltd. | E27: Toyota Boshoku Siam Metal. ( Thailand ) Co., Ltd.
B29: Payab P. | E29: K.Sirirat ( TIK )
B31: Date. | C31: 31/5/2010 | E31: Date.

Sheet YDT_Jun.10
B2: YARNAPUND DAISO (THAILAND) CO., LTD.
B4: 700/507 Moo. 2 T. Bannkao A. Phanthong Chonburi 20160
D6: Tel. : 038-454717-9 | F6: Fax. : 038-454721
A9: TO. : K. TIK ( TBSM ) | D9: FAX NO. : 038-210-018
A11: FROM : K. PAYAB ( YDT )
A14: STOCK CARD TBSM.
A15: On 30 June 2010
A18: ITEM | B18: PART CODE | C18: PART NO. | D18: PART NAME | E18: PACKING (pcs.) | F18: SAFETY STOCK YDT (pcs.) | G18: PART RECEIVE 30-6-10 (pcs.) | H18: TOTAL (box) | I18: TOTAL (pcs.)
A19: 1 | B19: YDT-001 | C19: 72516-X1400-00-F | D19: ARM RECLINING ADJUSTER RELEASE LH | E19: 100 | F19: 0 | G19: 100 | H19: 1 | I19: 100
A20: 2 | B20: YDT-002 | C20: 72515-X1400-00-F | D20: ARM RECLINING ADJUSTER RELEASE RH | E20: 100 | F20: 0 | G20: 200 | H20: 2 | I20: 200
A21: 3 | B21: YDT-007 | C21: 72515-X1F02-00-D | D21: ARM RECLINING ADJUSTER RELEASE RH | E21: 100 | F21: 1000 | G21: 600 | H21: 16 | I21: 1600
A22: 4 | B22: YDT-008 | C22: 72516-X1F02-00-D | D22: ARM RECLINING ADJUSTER RELEASE LH | E22: 100 | F22: 1000 | G22: 700 | H22: 17 | I22: 1700
B26: Yarnapund Daiso ( Thailand ) Co., Ltd. | E26: Toyota Boshoku Siam Metal. ( Thailand ) Co., Ltd.
B33: Date. | E33: Date.

Sheet YDT_Jul.10
B2: YARNAPUND DAISO (THAILAND) CO., LTD.
B4: 700/507 Moo. 2 T. Bannkao A. Phanthong Chonburi 20160
D6: Tel. : 038-454717-9 | G6: Fax. : 038-454721
A9: TO. : K. TIK ,Veerasak ( TBSM ) | D9: FAX NO. : 038-210-018
A11: FROM : K. PAYAB ( YDT )
A14: STOCK CARD TBSM.
A15: On 31 July 2010
A18: ITEM | B18: PART CODE | C18: PART NO. | D18: PART NAME | E18: PACKING (pcs.) | F18: SAFETY STOCK YDT (pcs.) | H18: PART RECEIVE 30-7-10 | J18: TOTAL STOCK
F19: Boxes | G19: Pcs | H19: Boxes | I19: Pcs | J19: Boxes | K19: Pcs
A20: 1 | B20: YDT-001 | C20: 72516-X1400-00-F | D20: ARM RECLINING ADJUSTER RELEASE LH | E20: 100 | F20: =+G20/E20 -> 0 | G20: 0 | H20: 2 | I20: =H20*100 -> 200 | J20: =F20+H20 -> 2 | K20: =G20+I20 -> 200
A21: 2 | B21: YDT-002 | C21: 72515-X1400-00-F | D21: ARM RECLINING ADJUSTER RELEASE RH | E21: 100 | F21: =+G21/E21 -> 0 | G21: 0 | H21: 1 | I21: =H21*100 -> 100 | J21: =F21+H21 -> 1 | K21: =G21+I21 -> 100
A22: 3 | B22: YDT-007 | C22: 72515-X1F02-00-D | D22: ARM RECLINING ADJUSTER RELEASE RH | E22: 100 | F22: =+G22/E22 -> 10 | G22: 1000 | H22: 2 | I22: =H22*100 -> 200 | J22: =F22+H22 -> 12 | K22: =G22+I22 -> 1200
A23: 4 | B23: YDT-008 | C23: 72516-X1F02-00-D | D23: ARM RECLINING ADJUSTER RELEASE LH | E23: 100 | F23: =+G23/E23 -> 10 | G23: 1000 | H23: 3 | I23: =H23*100 -> 300 | J23: =F23+H23 -> 13 | K23: =G23+I23 -> 1300
B27: Yarnapund Daiso ( Thailand ) Co., Ltd. | E27: Toyota Boshoku Siam Metal. ( Thailand ) Co., Ltd.
B29: Payab P.
B31: Date. | C31: 30/7/2010 | E31: Date.

Sheet YDT_Aug.10
B2: YARNAPUND DAISO (THAILAND) CO., LTD.
B4: 700/507 Moo. 2 T. Bannkao A. Phanthong Chonburi 20160
D6: Tel. : 038-454717-9 | F6: Fax. : 038-454721
A8: ATTN : K. TIK ,Veerasak ( TBSM ) | E8: FAX NO. : 038-210-018
A9: FROM : K. PAYAB ( YDT )
A11: STOCK CARD TBSM.
A12: On 31 Aug 2010
A15: ITEM | B15: PART CODE | C15: PART NO. | D15: PART NAME | E15: PACKING (pcs.) | F15: SAFETY STOCK YDT (pcs.) | H15: PART RECEIVE 31-8-10 | J15: TOTAL STOCK
F16: Boxes | G16: Pcs | H16: Boxes | I16: Pcs | J16: Boxes | K16: Pcs
A17: 1 | B17: YDT-001 | C17: 72516-X1400-00-F | D17: ARM RECLINING ADJUSTER RELEASE LH | E17: 100 | F17: =+G17/E17 -> 0 | G17: 0 | H17: 4 | I17: =H17*100 -> 400 | J17: =F17+H17 -> 4 | K17: =G17+I17 -> 400
A18: 2 | B18: YDT-002 | C18: 72515-X1400-00-F | D18: ARM RECLINING ADJUSTER RELEASE RH | E18: 100 | F18: =+G18/E18 -> 0 | G18: 0 | H18: 4 | I18: =H18*100 -> 400 | J18: =F18+H18 -> 4 | K18: =G18+I18 -> 400
A19: 3 | B19: YDT-007 | C19: 72515-X1F02-00-D | D19: ARM RECLINING ADJUSTER RELEASE RH | E19: 100 | F19: =+G19/E19 -> 10 | G19: 1000 | H19: 8 | I19: =H19*100 -> 800 | J19: =F19+H19 -> 18 | K19: =G19+I19 -> 1800
A20: 4 | B20: YDT-008 | C20: 72516-X1F02-00-D | D20: ARM RECLINING ADJUSTER RELEASE LH | E20: 100 | F20: =+G20/E20 -> 10 | G20: 1000 | H20: 8 | I20: =H20*100 -> 800 | J20: =F20+H20 -> 18 | K20: =G20+I20 -> 1800
C24: YARNAPUND DAISO(THAILAND)CO.,LTD | E24: TOYOTA BOSHOKU SIAM METAL(THAILAND)CO.,LTD
B26: Payab P.
B28: Date. | C28: 31/8/2010 | E28: Date.

Sheet YDT_Oct.10
B2: YARNAPUND DAISO (THAILAND) CO., LTD.
B4: 700/507 Moo. 2 T. Bannkao A. Phanthong Chonburi 20160
D6: Tel. : 038-454717-9 | F6: Fax. : 038-454721
A8: ATTN : K. TIK ,Veerasak ( TBSM ) | E8: FAX NO. : 038-210-018
A9: FROM : K. PAYAB ( YDT )
A11: STOCK CARD TBSM.
A12: On 29 Oct 2010
A15: ITEM | B15: PART CODE | C15: PART NO. | D15: PART NAME | E15: PACKING (pcs.) | F15: SAFETY STOCK YDT (pcs.) | H15: PART RECEIVE 29-10-10 | J15: TOTAL STOCK
F16: Boxes | G16: Pcs | H16: Boxes | I16: Pcs | J16: Boxes | K16: Pcs
A17: 1 | B17: YDT-001 | C17: 72516-X1400-00-F | D17: ARM RECLINING ADJUSTER RELEASE LH | E17: 100 | F17: =+G17/E17 -> 0 | G17: 0 | H17: 2 | I17: =H17*100 -> 200 | J17: =F17+H17 -> 2 | K17: =G17+I17 -> 200
A18: 2 | B18: YDT-002 | C18: 72515-X1400-00-F | D18: ARM RECLINING ADJUSTER RELEASE RH | E18: 100 | F18: =+G18/E18 -> 0 | G18: 0 | H18: 2 | I18: =H18*100 -> 200 | J18: =F18+H18 -> 2 | K18: =G18+I18 -> 200
A19: 3 | B19: YDT-007 | C19: 72515-X1F02-00-D | D19: ARM RECLINING ADJUSTER RELEASE RH | E19: 100 | F19: =+G19/E19 -> 10 | G19: 1000 | H19: 7 | I19: =H19*100 -> 700 | J19: =F19+H19 -> 17 | K19: =G19+I19 -> 1700
A20: 4 | B20: YDT-008 | C20: 72516-X1F02-00-D | D20: ARM RECLINING ADJUSTER RELEASE LH | E20: 100 | F20: =+G20/E20 -> 10 | G20: 1000 | H20: 7 | I20: =H20*100 -> 700 | J20: =F20+H20 -> 17 | K20: =G20+I20 -> 1700
C24: YARNAPUND DAISO(THAILAND)CO.,LTD | E24: TOYOTA BOSHOKU SIAM METAL(THAILAND)CO.,LTD
B26: Payab P.
B28: Date. | C28: 29/10/2010 | E28: Date.

Sheet YDT_Nov.10
B2: YARNAPUND DAISO (THAILAND) CO., LTD.
B4: 700/507 Moo. 2 T. Bannkao A. Phanthong Chonburi 20160
D6: Tel. : 038-454717-9 | F6: Fax. : 038-454721
A8: ATTN : K. TIK ,Veerasak ( TBSM ) | E8: FAX NO. : 038-210-018
A9: FROM : K. CHAIROT ( YDT )
A11: STOCK CARD TBSM.
A12: On 30 Nov 2010
A15: ITEM | B15: PART CODE | C15: PART NO. | D15: PART NAME | E15: PACKING (pcs.) | F15: SAFETY STOCK YDT (pcs.) | H15: PART RECEIVE 30-11-10 | J15: TOTAL STOCK
F16: Boxes | G16: Pcs | H16: Boxes | I16: Pcs | J16: Boxes | K16: Pcs
A17: 1 | B17: YDT-001 | C17: 72516-X1400-00-F | D17: ARM RECLINING ADJUSTER RELEASE LH | E17: 100 | F17: =+G17/E17 -> 0 | G17: 0 | H17: 2 | I17: =H17*100 -> 200 | J17: =F17+H17 -> 2 | K17: =G17+I17 -> 200
A18: 2 | B18: YDT-002 | C18: 72515-X1400-00-F | D18: ARM RECLINING ADJUSTER RELEASE RH | E18: 100 | F18: =+G18/E18 -> 0 | G18: 0 | H18: 2 | I18: =H18*100 -> 200 | J18: =F18+H18 -> 2 | K18: =G18+I18 -> 200
A19: 3 | B19: YDT-007 | C19: 72515-X1F02-00-D | D19: ARM RECLINING ADJUSTER RELEASE RH | E19: 100 | F19: =+G19/E19 -> 10 | G19: 1000 | H19: 6 | I19: =H19*100 -> 600 | J19: =F19+H19 -> 16 | K19: =G19+I19 -> 1600
A20: 4 | B20: YDT-008 | C20: 72516-X1F02-00-D | D20: ARM RECLINING ADJUSTER RELEASE LH | E20: 100 | F20: =+G20/E20 -> 10 | G20: 1000 | H20: 7 | I20: =H20*100 -> 700 | J20: =F20+H20 -> 17 | K20: =G20+I20 -> 1700
C24: YARNAPUND DAISO(THAILAND)CO.,LTD | E24: TOYOTA BOSHOKU SIAM METAL(THAILAND)CO.,LTD
B26: Chairot P.
B28: Date. | C28: 30/11/2010 | E28: Date.

Sheet YDT_Dec.10
B2: YARNAPUND DAISO (THAILAND) CO., LTD.
B4: 700/507 Moo. 2 T. Bannkao A. Phanthong Chonburi 20160
D6: Tel. : 038-454717-9 | F6: Fax. : 038-454721
A8: ATTN : K. TIK ,Veerasak ( TBSM ) | E8: FAX NO. : 038-210-018
A9: FROM : K. CHAIROT ( YDT )
A11: STOCK CARD TBSM.
A12: On 30 Dec 2010
A15: ITEM | B15: PART CODE | C15: PART NO. | D15: PART NAME | E15: PACKING (pcs.) | F15: SAFETY STOCK YDT (pcs.) | H15: PART RECEIVE 30-12-10 | J15: TOTAL STOCK
F16: Boxes | G16: Pcs | H16: Boxes | I16: Pcs | J16: Boxes | K16: Pcs
A17: 1 | B17: YDT-001 | C17: 72516-X1400-00-F | D17: ARM RECLINING ADJUSTER RELEASE LH | E17: 100 | F17: =+G17/E17 -> 0 | G17: 0 | H17: 2 | I17: =H17*100 -> 200 | J17: =F17+H17 -> 2 | K17: =G17+I17 -> 200
A18: 2 | B18: YDT-002 | C18: 72515-X1400-00-F | D18: ARM RECLINING ADJUSTER RELEASE RH | E18: 100 | F18: =+G18/E18 -> 0 | G18: 0 | H18: 3 | I18: =H18*100 -> 300 | J18: =F18+H18 -> 3 | K18: =G18+I18 -> 300
A19: 3 | B19: YDT-007 | C19: 72515-X1F02-00-D | D19: ARM RECLINING ADJUSTER RELEASE RH | E19: 100 | F19: =+G19/E19 -> 10 | G19: 1000 | H19: 6 | I19: =H19*100 -> 600 | J19: =F19+H19 -> 16 | K19: =G19+I19 -> 1600
A20: 4 | B20: YDT-008 | C20: 72516-X1F02-00-D | D20: ARM RECLINING ADJUSTER RELEASE LH | E20: 100 | F20: =+G20/E20 -> 10 | G20: 1000 | H20: 6 | I20: =H20*100 -> 600 | J20: =F20+H20 -> 16 | K20: =G20+I20 -> 1600
C24: YARNAPUND DAISO(THAILAND)CO.,LTD | E24: TOYOTA BOSHOKU SIAM METAL(THAILAND)CO.,LTD
B26: Chairot P.
B28: Date. | C28: 30/12/2010 | E28: Date.

Sheet YDT_Jan.11
B2: YARNAPUND DAISO (THAILAND) CO., LTD.
B4: 700/507 Moo. 2 T. Bannkao A. Phanthong Chonburi 20160
D6: Tel. : 038-454717-9 | F6: Fax. : 038-454721
A8: ATTN : K. TIK ,Veerasak ( TBSM ) | E8: FAX NO. : 038-210-018
A9: FROM : K. CHAIROT ( YDT )
A11: STOCK CARD TBSM.
A12: On 31 JAN 2011
A15: ITEM | B15: PART CODE | C15: PART NO. | D15: PART NAME | E15: PACKING (pcs.) | F15: SAFETY STOCK YDT (pcs.) | H15: PART RECEIVE 31-01-11 | J15: TOTAL STOCK
F16: Boxes | G16: Pcs | H16: Boxes | I16: Pcs | J16: Boxes | K16: Pcs
A17: 1 | B17: YDT-001 | C17: 72516-X1400-00-F | D17: ARM RECLINING ADJUSTER RELEASE LH | E17: 100 | F17: =+G17/E17 -> 0 | G17: 0 | H17: 2 | I17: =H17*100 -> 200 | J17: =F17+H17 -> 2 | K17: =G17+I17 -> 200
A18: 2 | B18: YDT-002 | C18: 72515-X1400-00-F | D18: ARM RECLINING ADJUSTER RELEASE RH | E18: 100 | F18: =+G18/E18 -> 0 | G18: 0 | H18: 2 | I18: =H18*100 -> 200 | J18: =F18+H18 -> 2 | K18: =G18+I18 -> 200
A19: 3 | B19: YDT-007 | C19: 72515-X1F02-00-D | D19: ARM RECLINING ADJUSTER RELEASE RH | E19: 100 | F19: =+G19/E19 -> 10 | G19: 1000 | H19: 4 | I19: =H19*100 -> 400 | J19: =F19+H19 -> 14 | K19: =G19+I19 -> 1400
A20: 4 | B20: YDT-008 | C20: 72516-X1F02-00-D | D20: ARM RECLINING ADJUSTER RELEASE LH | E20: 100 | F20: =+G20/E20 -> 10 | G20: 1000 | H20: 4 | I20: =H20*100 -> 400 | J20: =F20+H20 -> 14 | K20: =G20+I20 -> 1400
C24: YARNAPUND DAISO(THAILAND)CO.,LTD | E24: TOYOTA BOSHOKU SIAM METAL(THAILAND)CO.,LTD
B26: Chairot P.
B28: Date. | C28: 02/02/2011 | E28: Date.

Sheet Part_Ending Check
A1: Raw Matetial | C1: =#REF! -> #REF! | N1: Ending - Beg. | O1: % Ending | P1: Ending Up | Q1: Ending Down | R1: Ending
A2: Supplier | B2: Back_No. | C2: Parts_No. | D2: Parts_Name | E2: Qty_per_Pallet | F2: Q'ty Beginning | G2: Q'ty Purchase | H2: Q'ty Stamping | I2: Q'ty Out from W/H | J2: Q'ty Ending | K2: Unit Cost | L2: Amount (THB) | N2: Q'ty | O2: Up / Down | P2: >= 30% | Q2: <=-30% | R2: Diff Amount (THB)
A3: A010-1 | B3: AOY001 | C3: 72641-0K020 | D3: RIVET | E3: 2000 | F3: =SUMIF(#REF!,B3,#REF!) -> #REF! | G3: =SUMIF(#REF!,B3,#REF!) -> #REF! | H3: =SUMIF(#REF!,B3,#REF!) -> #REF! | I3: =SUMIF(#REF!,B3,#REF!)*-1 -> #REF! | J3: =SUM(F3:I3) -> #REF! | K3: =VLOOKUP(B3,#REF!,21,0) -> #REF! | L3: =J3*K3 -> #REF! | M3: Parts | N3: =J3-F3 -> #REF! | O3: =IF(ISERROR(IF(N3=0,0,(N3/F3))),"New Stock",(IF(N3=0,0,(N3/F3)))) -> New Stock | P3: =IF(O3>=30%,O3,"-") -> New Stock | Q3: =IF(O3<=-30%,O3,"-") -> - | R3: =N3*K3 -> #REF!
A4: A010-1 | B4: AOY002 | C4: 90174-T0003 | D4: NUT WELD | E4: 1000 | F4: =SUMIF(#REF!,B4,#REF!) -> #REF! | G4: =SUMIF(#REF!,B4,#REF!) -> #REF! | H4: =SUMIF(#REF!,B4,#REF!) -> #REF! | I4: =SUMIF(#REF!,B4,#REF!)*-1 -> #REF! | J4: =SUM(F4:I4) -> #REF! | K4: =VLOOKUP(B4,#REF!,21,0) -> #REF! | L4: =J4*K4 -> #REF! | M4: Parts | N4: =J4-F4 -> #REF! | O4: =IF(ISERROR(IF(N4=0,0,(N4/F4))),"New Stock",(IF(N4=0,0,(N4/F4)))) -> New Stock | P4: =IF(O4>=30%,O4,"-") -> New Stock | Q4: =IF(O4<=-30%,O4,"-") -> - | R4: =N4*K4 -> #REF!
A5: A010-1 | B5: AOY003 | C5: 90174-T0004 | D5: NUT WELD | E5: 500 | F5: =SUMIF(#REF!,B5,#REF!) -> #REF! | G5: =SUMIF(#REF!,B5,#REF!) -> #REF! | H5: =SUMIF(#REF!,B5,#REF!) -> #REF! | I5: =SUMIF(#REF!,B5,#REF!)*-1 -> #REF! | J5: =SUM(F5:I5) -> #REF! | K5: =VLOOKUP(B5,#REF!,21,0) -> #REF! | L5: =J5*K5 -> #REF! | M5: Parts | N5: =J5-F5 -> #REF! | O5: =IF(ISERROR(IF(N5=0,0,(N5/F5))),"New Stock",(IF(N5=0,0,(N5/F5)))) -> New Stock | P5: =IF(O5>=30%,O5,"-") -> New Stock | Q5: =IF(O5<=-30%,O5,"-") -> - | R5: =N5*K5 -> #REF!
A6: A010-1 | B6: AOY004 | C6: 90174-08039 | D6: NUT WELD | E6: 2000 | F6: =SUMIF(#REF!,B6,#REF!) -> #REF! | G6: =SUMIF(#REF!,B6,#REF!) -> #REF! | H6: =SUMIF(#REF!,B6,#REF!) -> #REF! | I6: =SUMIF(#REF!,B6,#REF!)*-1 -> #REF! | J6: =SUM(F6:I6) -> #REF! | K6: =VLOOKUP(B6,#REF!,21,0) -> #REF! | L6: =J6*K6 -> #REF! | M6: Parts | N6: =J6-F6 -> #REF! | O6: =IF(ISERROR(IF(N6=0,0,(N6/F6))),"New Stock",(IF(N6=0,0,(N6/F6)))) -> New Stock | P6: =IF(O6>=30%,O6,"-") -> New Stock | Q6: =IF(O6<=-30%,O6,"-") -> - | R6: =N6*K6 -> #REF!
A7: B001-1 | B7: BTS010 | C7: 71897-X7A01 | D7: HOOK SEAT COVER SIDE | E7: 500 | F7: =SUMIF(#REF!,B7,#REF!) -> #REF! | G7: =SUMIF(#REF!,B7,#REF!) -> #REF! | H7: =SUMIF(#REF!,B7,#REF!) -> #REF! | I7: =SUMIF(#REF!,B7,#REF!)*-1 -> #REF! | J7: =SUM(F7:I7) -> #REF! | K7: =VLOOKUP(B7,#REF!,21,0) -> #REF! | L7: =J7*K7 -> #REF! | M7: Parts | N7: =J7-F7 -> #REF! | O7: =IF(ISERROR(IF(N7=0,0,(N7/F7))),"New Stock",(IF(N7=0,0,(N7/F7)))) -> New Stock | P7: =IF(O7>=30%,O7,"-") -> New Stock | Q7: =IF(O7<=-30%,O7,"-") -> - | R7: =N7*K7 -> #REF!
A8: B001-1 | B8: BTS011 | C8: 72558-X7A00 | D8: STOPPER RECLINING | E8: 200 | F8: =SUMIF(#REF!,B8,#REF!) -> #REF! | G8: =SUMIF(#REF!,B8,#REF!) -> #REF! | H8: =SUMIF(#REF!,B8,#REF!) -> #REF! | I8: =SUMIF(#REF!,B8,#REF!)*-1 -> #REF! | J8: =SUM(F8:I8) -> #REF! | K8: =VLOOKUP(B8,#REF!,21,0) -> #REF! | L8: =J8*K8 -> #REF! | M8: Parts | N8: =J8-F8 -> #REF! | O8: =IF(ISERROR(IF(N8=0,0,(N8/F8))),"New Stock",(IF(N8=0,0,(N8/F8)))) -> New Stock | P8: =IF(O8>=30%,O8,"-") -> New Stock | Q8: =IF(O8<=-30%,O8,"-") -> - | R8: =N8*K8 -> #REF!
A9: B001-1 | B9: BTS012 | C9: 72558-X7A01 | D9: STOPPER RECLINING | E9: 200 | F9: =SUMIF(#REF!,B9,#REF!) -> #REF! | G9: =SUMIF(#REF!,B9,#REF!) -> #REF! | H9: =SUMIF(#REF!,B9,#REF!) -> #REF! | I9: =SUMIF(#REF!,B9,#REF!)*-1 -> #REF! | J9: =SUM(F9:I9) -> #REF! | K9: =VLOOKUP(B9,#REF!,21,0) -> #REF! | L9: =J9*K9 -> #REF! | M9: Parts | N9: =J9-F9 -> #REF! | O9: =IF(ISERROR(IF(N9=0,0,(N9/F9))),"New Stock",(IF(N9=0,0,(N9/F9)))) -> New Stock | P9: =IF(O9>=30%,O9,"-") -> New Stock | Q9: =IF(O9<=-30%,O9,"-") -> - | R9: =N9*K9 -> #REF!
A10: B001-1 | B10: BTS013 | C10: 72777-X7A00 | D10: PLATE RR SEAT RECLINING BRACKET | E10: 400 | F10: =SUMIF(#REF!,B10,#REF!) -> #REF! | G10: =SUMIF(#REF!,B10,#REF!) -> #REF! | H10: =SUMIF(#REF!,B10,#REF!) -> #REF! | I10: =SUMIF(#REF!,B10,#REF!)*-1 -> #REF! | J10: =SUM(F10:I10) -> #REF! | K10: =VLOOKUP(B10,#REF!,21,0) -> #REF! | L10: =J10*K10 -> #REF! | M10: Parts | N10: =J10-F10 -> #REF! | O10: =IF(ISERROR(IF(N10=0,0,(N10/F10))),"New Stock",(IF(N10=0,0,(N10/F10)))) -> New Stock | P10: =IF(O10>=30%,O10,"-") -> New Stock | Q10: =IF(O10<=-30%,O10,"-") -> - | R10: =N10*K10 -> #REF!
A11: B001-1 | B11: BTS014 | C11: 72777-X7A01 | D11: PLATE RR SEAT RECLINING BRACKET | E11: 400 | F11: =SUMIF(#REF!,B11,#REF!) -> #REF! | G11: =SUMIF(#REF!,B11,#REF!) -> #REF! | H11: =SUMIF(#REF!,B11,#REF!) -> #REF! | I11: =SUMIF(#REF!,B11,#REF!)*-1 -> #REF! | J11: =SUM(F11:I11) -> #REF! | K11: =VLOOKUP(B11,#REF!,21,0) -> #REF! | L11: =J11*K11 -> #REF! | M11: Parts | N11: =J11-F11 -> #REF! | O11: =IF(ISERROR(IF(N11=0,0,(N11/F11))),"New Stock",(IF(N11=0,0,(N11/F11)))) -> New Stock | P11: =IF(O11>=30%,O11,"-") -> New Stock | Q11: =IF(O11<=-30%,O11,"-") -> - | R11: =N11*K11 -> #REF!
A12: B001-1 | B12: BTS015 | C12: 72441-X7A00 | D12: LINK VERTICAL TRAVEL NO1 | E12: 100 | F12: =SUMIF(#REF!,B12,#REF!) -> #REF! | G12: =SUMIF(#REF!,B12,#REF!) -> #REF! | H12: =SUMIF(#REF!,B12,#REF!) -> #REF! | I12: =SUMIF(#REF!,B12,#REF!)*-1 -> #REF! | J12: =SUM(F12:I12) -> #REF! | K12: =VLOOKUP(B12,#REF!,21,0) -> #REF! | L12: =J12*K12 -> #REF! | M12: Parts | N12: =J12-F12 -> #REF! | O12: =IF(ISERROR(IF(N12=0,0,(N12/F12))),"New Stock",(IF(N12=0,0,(N12/F12)))) -> New Stock | P12: =IF(O12>=30%,O12,"-") -> New Stock | Q12: =IF(O12<=-30%,O12,"-") -> - | R12: =N12*K12 -> #REF!
A13: B001-1 | B13: BTS016 | C13: 72291-X7A00 | D13: PLATE SEAT TRACK MEMORY NO1 | E13: 200 | F13: =SUMIF(#REF!,B13,#REF!) -> #REF! | G13: =SUMIF(#REF!,B13,#REF!) -> #REF! | H13: =SUMIF(#REF!,B13,#REF!) -> #REF! | I13: =SUMIF(#REF!,B13,#REF!)*-1 -> #REF! | J13: =SUM(F13:I13) -> #REF! | K13: =VLOOKUP(B13,#REF!,21,0) -> #REF! | L13: =J13*K13 -> #REF! | M13: Parts | N13: =J13-F13 -> #REF! | O13: =IF(ISERROR(IF(N13=0,0,(N13/F13))),"New Stock",(IF(N13=0,0,(N13/F13)))) -> New Stock | P13: =IF(O13>=30%,O13,"-") -> New Stock | Q13: =IF(O13<=-30%,O13,"-") -> - | R13: =N13*K13 -> #REF!
A14: B001-1 | B14: BTS017 | C14: 72291-X7A02 | D14: PLATE SEAT TRACK MEMORY NO1 | E14: 1000 | F14: =SUMIF(#REF!,B14,#REF!) -> #REF! | G14: =SUMIF(#REF!,B14,#REF!) -> #REF! | H14: =SUMIF(#REF!,B14,#REF!) -> #REF! | I14: =SUMIF(#REF!,B14,#REF!)*-1 -> #REF! | J14: =SUM(F14:I14) -> #REF! | K14: =VLOOKUP(B14,#REF!,21,0) -> #REF! | L14: =J14*K14 -> #REF! | M14: Parts | N14: =J14-F14 -> #REF! | O14: =IF(ISERROR(IF(N14=0,0,(N14/F14))),"New Stock",(IF(N14=0,0,(N14/F14)))) -> New Stock | P14: =IF(O14>=30%,O14,"-") -> New Stock | Q14: =IF(O14<=-30%,O14,"-") -> - | R14: =N14*K14 -> #REF!
... A623: Z000-1 | B623: N32-29 | C623: 72534-X1Y02 | D623: PAW1 LH | E623: 0 | F623: =SUMIF(#REF!,B623,#REF!) -> #REF! | G623: =SUMIF(#REF!,B623,#REF!) -> #REF! | H623: =SUMIF(#REF!,B623,#REF!) -> #REF! | I623: =SUMIF(#REF!,B623,#REF!)*-1 -> #REF! | J623: =SUM(F623:I623) -> #REF! | K623: =VLOOKUP(B623,#REF!,21,0) -> #REF! | L623: =J623*K623 -> #REF! | M623: Press | N623: =J623-F623 -> #REF! | O623: =IF(ISERROR(IF(N623=0,0,(N623/F623))),"New Stock",(IF(N623=0,0,(N623/F623)))) -> New Stock | P623: =IF(O623>=30%,O623,"-") -> New Stock | Q623: =IF(O623<=-30%,O623,"-") -> - | R623: =N623*K623 -> #REF!
D625: TOTAL | F625: =SUM(F3:F624) -> #REF! | G625: =SUM(G3:G624) -> #REF! | H625: =SUM(H3:H624) -> #REF! | I625: =SUM(I3:I624) -> #REF! | J625: =SUM(J3:J624) -> #REF! | L625: =SUM(L3:L624) -> #REF! | N625: =SUM(N3:N624) -> #REF! | R625: =SUM(R3:R624) -> #REF!
D626: Percentage | F626: =F625/F625 -> #REF! | J626: =J625/F625 -> #REF! | N626: =N625/F625 -> #REF!
F627: =SUBTOTAL(9,F3:F624) -> #REF! | G627: =SUBTOTAL(9,G3:G624) -> #REF! | H627: =SUBTOTAL(9,H3:H624) -> #REF! | I627: =SUBTOTAL(9,I3:I624) -> #REF! | J627: =SUBTOTAL(9,J3:J624) -> #REF! | L627: =SUBTOTAL(9,L3:L624) -> #REF! | N627: =SUBTOTAL(9,N3:N624) -> #REF! | R627: =SUBTOTAL(9,R3:R624) -> #REF!
E629: Check | F629: =#REF! -> #REF! | G629: =#REF! -> #REF! | H629: =#REF! -> #REF! | I629: =#REF! -> #REF! | J629: =#REF! -> #REF! | L629: =#REF! -> #REF!
E630: Diff | F630: =F625-F629 -> #REF! | G630: =G625-G629 -> #REF! | H630: =H625-H629 -> #REF! | I630: =I625-I629 -> #REF! | J630: =J625-J629 -> #REF! | L630: =L625-L629 -> #REF!

Sheet FG_Ending Check
A1: Finish Goods | C1: =#REF! -> #REF! | K1: Ending - Beg. | L1: % Ending | M1: Ending Up | N1: Ending Down
A2: Back_No. | B2: Cus._FG_No. | C2: Cus._FG_Name | D2: Qty_per_Pallet | E2: Beginning | F2: FG_Production | G2: Sales | H2: NG | I2: Ending | J2: Model | K2: Q'ty | L2: Up / Down | M2: >= 30% | N2: <=-30%
A3: 030-05 | B3: 79030-0K010-E1 | C3: LEG ASSY RR NO2 RH | D3: 6 | E3: =SUMIF(#REF!,A3,#REF!) -> #REF! | F3: =SUMIF(#REF!,A3,#REF!) -> #REF! | G3: =SUMIF(#REF!,A3,#REF!)*-1 -> #REF! | H3: =SUMIF(#REF!,A3,#REF!)*-1 -> #REF! | I3: =SUM(E3:H3) -> #REF! | J3: =VLOOKUP(A3,#REF!,3,0) -> #REF! | K3: =I3-E3 -> #REF! | L3: =IF(ISERROR(IF(K3=0,0,(K3/E3))),"New Stock",(IF(K3=0,0,(K3/E3)))) -> New Stock | M3: =IF(L3>=30%,L3,"-") -> New Stock | N3: =IF(L3<=-30%,L3,"-") -> -
A4: 030-06 | B4: 79040-0K010-E1 | C4: LEG ASSY RR NO2 LH | D4: 6 | E4: =SUMIF(#REF!,A4,#REF!) -> #REF! | F4: =SUMIF(#REF!,A4,#REF!) -> #REF! | G4: =SUMIF(#REF!,A4,#REF!)*-1 -> #REF! | H4: =SUMIF(#REF!,A4,#REF!)*-1 -> #REF! | I4: =SUM(E4:H4) -> #REF! | J4: =VLOOKUP(A4,#REF!,3,0) -> #REF! | K4: =I4-E4 -> #REF! | L4: =IF(ISERROR(IF(K4=0,0,(K4/E4))),"New Stock",(IF(K4=0,0,(K4/E4)))) -> New Stock | M4: =IF(L4>=30%,L4,"-") -> New Stock | N4: =IF(L4<=-30%,L4,"-") -> -
A5: 030-07 | B5: 79030-0K010-E0 | C5: LEG ASSY RR NO2 RH | D5: 6 | E5: =SUMIF(#REF!,A5,#REF!) -> #REF! | F5: =SUMIF(#REF!,A5,#REF!) -> #REF! | G5: =SUMIF(#REF!,A5,#REF!)*-1 -> #REF! | H5: =SUMIF(#REF!,A5,#REF!)*-1 -> #REF! | I5: =SUM(E5:H5) -> #REF! | J5: =VLOOKUP(A5,#REF!,3,0) -> #REF! | K5: =I5-E5 -> #REF! | L5: =IF(ISERROR(IF(K5=0,0,(K5/E5))),"New Stock",(IF(K5=0,0,(K5/E5)))) -> New Stock | M5: =IF(L5>=30%,L5,"-") -> New Stock | N5: =IF(L5<=-30%,L5,"-") -> -
A6: 030-08 | B6: 79040-0K010-E0 | C6: LEG ASSY RR NO2 LH | D6: 6 | E6: =SUMIF(#REF!,A6,#REF!) -> #REF! | F6: =SUMIF(#REF!,A6,#REF!) -> #REF! | G6: =SUMIF(#REF!,A6,#REF!)*-1 -> #REF! | H6: =SUMIF(#REF!,A6,#REF!)*-1 -> #REF! | I6: =SUM(E6:H6) -> #REF! | J6: =VLOOKUP(A6,#REF!,3,0) -> #REF! | K6: =I6-E6 -> #REF! | L6: =IF(ISERROR(IF(K6=0,0,(K6/E6))),"New Stock",(IF(K6=0,0,(K6/E6)))) -> New Stock | M6: =IF(L6>=30%,L6,"-") -> New Stock | N6: =IF(L6<=-30%,L6,"-") -> -
A7: 150-13 | B7: 72503-X7A01 | C7: ARM SUB-ASSY, RECLINING ADJUSTER, LWR RH | D7: 12 | E7: =SUMIF(#REF!,A7,#REF!) -> #REF! | F7: =SUMIF(#REF!,A7,#REF!) -> #REF! | G7: =SUMIF(#REF!,A7,#REF!)*-1 -> #REF! | H7: =SUMIF(#REF!,A7,#REF!)*-1 -> #REF! | I7: =SUM(E7:H7) -> #REF! | J7: =VLOOKUP(A7,#REF!,3,0) -> #REF! | K7: =I7-E7 -> #REF! | L7: =IF(ISERROR(IF(K7=0,0,(K7/E7))),"New Stock",(IF(K7=0,0,(K7/E7)))) -> New Stock | M7: =IF(L7>=30%,L7,"-") -> New Stock | N7: =IF(L7<=-30%,L7,"-") -> -
A8: 150-14 | B8: 72504-X1410 | C8: ARM SUB-ASSY, RECLINING ADJUSTER, LWR LH | D8: 8 | E8: =SUMIF(#REF!,A8,#REF!) -> #REF! | F8: =SUMIF(#REF!,A8,#REF!) -> #REF! | G8: =SUMIF(#REF!,A8,#REF!)*-1 -> #REF! | H8: =SUMIF(#REF!,A8,#REF!)*-1 -> #REF! | I8: =SUM(E8:H8) -> #REF! | J8: =VLOOKUP(A8,#REF!,3,0) -> #REF! | K8: =I8-E8 -> #REF! | L8: =IF(ISERROR(IF(K8=0,0,(K8/E8))),"New Stock",(IF(K8=0,0,(K8/E8)))) -> New Stock | M8: =IF(L8>=30%,L8,"-") -> New Stock | N8: =IF(L8<=-30%,L8,"-") -> -
A9: 150-15 | B9: 72503-X7A02 | C9: ARM SUB-ASSY, RECLINING ADJUSTER, LWR RH | D9: 8 | E9: =SUMIF(#REF!,A9,#REF!) -> #REF! | F9: =SUMIF(#REF!,A9,#REF!) -> #REF! | G9: =SUMIF(#REF!,A9,#REF!)*-1 -> #REF! | H9: =SUMIF(#REF!,A9,#REF!)*-1 -> #REF! | I9: =SUM(E9:H9) -> #REF! | J9: =VLOOKUP(A9,#REF!,3,0) -> #REF! | K9: =I9-E9 -> #REF! | L9: =IF(ISERROR(IF(K9=0,0,(K9/E9))),"New Stock",(IF(K9=0,0,(K9/E9)))) -> New Stock | M9: =IF(L9>=30%,L9,"-") -> New Stock | N9: =IF(L9<=-30%,L9,"-") -> -
A10: 150-16 | B10: 72504-X1F05 | C10: ARM SUB-ASSY, RECLINING ADJUSTER, LWR LH | D10: 12 | E10: =SUMIF(#REF!,A10,#REF!) -> #REF! | F10: =SUMIF(#REF!,A10,#REF!) -> #REF! | G10: =SUMIF(#REF!,A10,#REF!)*-1 -> #REF! | H10: =SUMIF(#REF!,A10,#REF!)*-1 -> #REF! | I10: =SUM(E10:H10) -> #REF! | J10: =VLOOKUP(A10,#REF!,3,0) -> #REF! | K10: =I10-E10 -> #REF! | L10: =IF(ISERROR(IF(K10=0,0,(K10/E10))),"New Stock",(IF(K10=0,0,(K10/E10)))) -> New Stock | M10: =IF(L10>=30%,L10,"-") -> New Stock | N10: =IF(L10<=-30%,L10,"-") -> -
A11: 152-01 | B11: 72503-X1F00 | C11: ARM SUB-ASSY, RECLINING ADJUSTER, LWR RH | D11: 8 | E11: =SUMIF(#REF!,A11,#REF!) -> #REF! | F11: =SUMIF(#REF!,A11,#REF!) -> #REF! | G11: =SUMIF(#REF!,A11,#REF!)*-1 -> #REF! | H11: =SUMIF(#REF!,A11,#REF!)*-1 -> #REF! | I11: =SUM(E11:H11) -> #REF! | J11: =VLOOKUP(A11,#REF!,3,0) -> #REF! | K11: =I11-E11 -> #REF! | L11: =IF(ISERROR(IF(K11=0,0,(K11/E11))),"New Stock",(IF(K11=0,0,(K11/E11)))) -> New Stock | M11: =IF(L11>=30%,L11,"-") -> New Stock | N11: =IF(L11<=-30%,L11,"-") -> -
A12: 152-02 | B12: 72504-X1F00 | C12: ARM SUB-ASSY, RECLINING ADJUSTER, LWR LH | D12: 16 | E12: =SUMIF(#REF!,A12,#REF!) -> #REF! | F12: =SUMIF(#REF!,A12,#REF!) -> #REF! | G12: =SUMIF(#REF!,A12,#REF!)*-1 -> #REF! | H12: =SUMIF(#REF!,A12,#REF!)*-1 -> #REF! | I12: =SUM(E12:H12) -> #REF! | J12: =VLOOKUP(A12,#REF!,3,0) -> #REF! | K12: =I12-E12 -> #REF! | L12: =IF(ISERROR(IF(K12=0,0,(K12/E12))),"New Stock",(IF(K12=0,0,(K12/E12)))) -> New Stock | M12: =IF(L12>=30%,L12,"-") -> New Stock | N12: =IF(L12<=-30%,L12,"-") -> -
A13: 152-03 | B13: 72503-X1F01 | C13: ARM SUB-ASSY, RECLINING ADJUSTER, LWR RH | D13: 16 | E13: =SUMIF(#REF!,A13,#REF!) -> #REF! | F13: =SUMIF(#REF!,A13,#REF!) -> #REF! | G13: =SUMIF(#REF!,A13,#REF!)*-1 -> #REF! | H13: =SUMIF(#REF!,A13,#REF!)*-1 -> #REF! | I13: =SUM(E13:H13) -> #REF! | J13: =VLOOKUP(A13,#REF!,3,0) -> #REF! | K13: =I13-E13 -> #REF! | L13: =IF(ISERROR(IF(K13=0,0,(K13/E13))),"New Stock",(IF(K13=0,0,(K13/E13)))) -> New Stock | M13: =IF(L13>=30%,L13,"-") -> New Stock | N13: =IF(L13<=-30%,L13,"-") -> -
A14: 152-04 | B14: 72504-X1F01 | C14: ARM SUB-ASSY, RECLINING ADJUSTER, LWR LH | D14: 8 | E14: =SUMIF(#REF!,A14,#REF!) -> #REF! | F14: =SUMIF(#REF!,A14,#REF!) -> #REF! | G14: =SUMIF(#REF!,A14,#REF!)*-1 -> #REF! | H14: =SUMIF(#REF!,A14,#REF!)*-1 -> #REF! | I14: =SUM(E14:H14) -> #REF! | J14: =VLOOKUP(A14,#REF!,3,0) -> #REF! | K14: =I14-E14 -> #REF! | L14: =IF(ISERROR(IF(K14=0,0,(K14/E14))),"New Stock",(IF(K14=0,0,(K14/E14)))) -> New Stock | M14: =IF(L14>=30%,L14,"-") -> New Stock | N14: =IF(L14<=-30%,L14,"-") -> -
... A231: ZA0-31 | B231: 72693-0K040 | C231: HOOK REAR SEAT CUSHION LOCK | D231: 150 | E231: =SUMIF(#REF!,A231,#REF!) -> #REF! | F231: =SUMIF(#REF!,A231,#REF!) -> #REF! | G231: =SUMIF(#REF!,A231,#REF!)*-1 -> #REF! | H231: =SUMIF(#REF!,A231,#REF!)*-1 -> #REF! | I231: =SUM(E231:H231) -> #REF! | J231: =VLOOKUP(A231,#REF!,3,0) -> #REF! | K231: =I231-E231 -> #REF! | L231: =IF(ISERROR(IF(K231=0,0,(K231/E231))),"New Stock",(IF(K231=0,0,(K231/E231)))) -> New Stock | M231: =IF(L231>=30%,L231,"-") -> New Stock | N231: =IF(L231<=-30%,L231,"-") -> -
