Workbook

Sheet Append2
A1: Line | B1: SD No. | C1: Part No. | D1: Part Name | E1: 1 | F1: 2 | G1: 3 | H1: 4 | I1: 5 | J1: 6 | K1: 7 | L1: 8 | M1: 9 | N1: 10 | O1: 11 | P1: 12 | Q1: 13 | R1: 14 | S1: 15 | T1: 16 | U1: 17 | V1: 18 | W1: 19 | X1: 20 | Y1: 21 | Z1: 22 | AA1: 23 | AB1: 24 | AC1: 25 | AD1: 26 | AE1: 27 | AF1: 28 | AG1: 29 | AH1: 30 | AI1: 31 | AJ1: Total
A2: 20 | B2: GB0-02 | C2: 72211-0K050 | D2: 2ND HANDLE 4 | E2: 13 | F2: 12 | G2: 9 | H2: 14 | I2: 0 | J2: 0 | K2: 0 | L2: 11 | M2: 0 | N2: 15 | O2: 0 | P2: 0 | Q2: 0 | R2: 0 | S2: 0 | T2: 0 | U2: 0 | V2: 0 | W2: 0 | X2: 0 | Y2: 0 | Z2: 11 | AA2: 0 | AB2: 0 | AC2: 0 | AD2: 0 | AE2: 0 | AF2: 9 | AG2: 0 | AH2: 0 | AI2: 0 | AJ2: 94
A3: 20 | B3: IRD-63 | C3: 72506-X7A04 | D3: ROD SUB-ASSY, RECLINING CONNECTING | E3: 0 | F3: 0 | G3: 0 | H3: 0 | I3: 0 | J3: 0 | K3: 0 | L3: 0 | M3: 0 | N3: 0 | O3: 0 | P3: 0 | Q3: 0 | R3: 0 | S3: 0 | T3: 0 | U3: 0 | V3: 0 | W3: 0 | X3: 0 | Y3: 0 | Z3: 0 | AA3: 0 | AB3: 0 | AC3: 0 | AD3: 0 | AE3: 0 | AF3: 0 | AG3: 0 | AH3: 0 | AI3: 0 | AJ3: 0
A4: 20 | B4: IRD-64 | C4: 72506-X7V00 | D4: ROD SUB-ASSY, RECLINING CONNECTING | E4: 0 | F4: 0 | G4: 0 | H4: 0 | I4: 0 | J4: 0 | K4: 0 | L4: 0 | M4: 0 | N4: 0 | O4: 0 | P4: 0 | Q4: 0 | R4: 0 | S4: 0 | T4: 0 | U4: 0 | V4: 0 | W4: 0 | X4: 0 | Y4: 0 | Z4: 0 | AA4: 0 | AB4: 0 | AC4: 0 | AD4: 0 | AE4: 0 | AF4: 0 | AG4: 0 | AH4: 0 | AI4: 0 | AJ4: 0
A5: 20 | B5: CRC-56 | D5: ROD SUB-ASSY, RECLINING CONNECTING | E5: 0 | F5: 0 | G5: 0 | H5: 0 | I5: 0 | J5: 0 | K5: 0 | L5: 0 | M5: 0 | N5: 0 | O5: 0 | P5: 0 | Q5: 0 | R5: 0 | S5: 0 | T5: 0 | U5: 0 | V5: 0 | W5: 0 | X5: 0 | Y5: 0 | Z5: 0 | AA5: 0 | AB5: 0 | AC5: 0 | AD5: 0 | AE5: 0 | AF5: 0 | AG5: 0 | AH5: 0 | AI5: 0 | AJ5: 0
A6: 20 | B6: IRD-77 | C6: 72659-X7A09 | D6: ROD RR SEAT BACK LOCK CONNECTING | E6: 0 | F6: 0 | G6: 0 | H6: 0 | I6: 0 | J6: 0 | K6: 0 | L6: 0 | M6: 0 | N6: 0 | O6: 0 | P6: 0 | Q6: 0 | R6: 0 | S6: 0 | T6: 0 | U6: 0 | V6: 0 | W6: 0 | X6: 0 | Y6: 0 | Z6: 0 | AA6: 0 | AB6: 0 | AC6: 0 | AD6: 0 | AE6: 0 | AF6: 0 | AG6: 0 | AH6: 0 | AI6: 0 | AJ6: 0
A7: 20 | B7: TOP-311 | E7: 0 | F7: 0 | G7: 0 | H7: 0 | I7: 0 | J7: 0 | K7: 0 | L7: 0 | M7: 0 | N7: 0 | O7: 0 | P7: 0 | Q7: 0 | R7: 0 | S7: 0 | T7: 0 | U7: 0 | V7: 0 | W7: 0 | X7: 0 | Y7: 0 | Z7: 0 | AA7: 0 | AB7: 0 | AC7: 0 | AD7: 0 | AE7: 0 | AF7: 0 | AG7: 0 | AH7: 0 | AI7: 0 | AJ7: 0
A8: 20 | B8: GB0-02-T | D8: TEST MC | E8: 44 | F8: 0 | G8: 0 | H8: 0 | I8: 0 | J8: 0 | K8: 0 | L8: 0 | M8: 0 | N8: 17 | O8: 19 | P8: 16 | Q8: 0 | R8: 0 | S8: 15 | T8: 13 | U8: 11 | V8: 10 | W8: 0 | X8: 0 | Y8: 0 | Z8: 0 | AA8: 18 | AB8: 18 | AC8: 5 | AD8: 0 | AE8: 0 | AF8: 0 | AG8: 0 | AH8: 0 | AI8: 0 | AJ8: 186
A9: 570 | B9: N32-18 | C9: 72523-X1M06 | D9: Guidde Plate | E9: 0 | F9: 2 | G9: 0 | H9: 9 | I9: 0 | J9: 0 | K9: 0 | L9: 0 | M9: 0 | N9: 0 | O9: 17 | P9: 1 | Q9: 0 | R9: 0 | S9: 0 | T9: 0 | U9: 8 | V9: 21 | W9: 6 | X9: 6 | Y9: 0 | Z9: 4 | AA9: 0 | AB9: 0 | AC9: 0 | AD9: 0 | AE9: 0 | AF9: 0 | AG9: 0 | AH9: 0 | AI9: 0 | AJ9: 74
A10: 570 | B10: N32-02 | C10: 72531-X1C02 | D10: Rachet | E10: 0 | F10: 2 | G10: 0 | H10: 10 | I10: 0 | J10: 0 | K10: 0 | L10: 2 | M10: 0 | N10: 0 | O10: 19 | P10: 1 | Q10: 0 | R10: 0 | S10: 0 | T10: 0 | U10: 0 | V10: 22 | W10: 0 | X10: 0 | Y10: 0 | Z10: 2 | AA10: 0 | AB10: 0 | AC10: 3 | AD10: 0 | AE10: 0 | AF10: 0 | AG10: 0 | AH10: 0 | AI10: 0 | AJ10: 61
A11: 570 | B11: N32-27 | C11: 72531-X1F00 | D11: Ring Plate | E11: 0 | F11: 1 | G11: 6 | H11: 124 | I11: 0 | J11: 0 | K11: 0 | L11: 0 | M11: 0 | N11: 0 | O11: 150 | P11: 0 | Q11: 0 | R11: 0 | S11: 1 | T11: 0 | U11: 4 | V11: 147 | W11: 0 | X11: 0 | Y11: 0 | Z11: 20 | AA11: 2 | AB11: 0 | AC11: 0 | AD11: 0 | AE11: 0 | AF11: 0 | AG11: 0 | AH11: 0 | AI11: 0 | AJ11: 455
A12: 570 | B12: DTT001 | C12: 72533-X1Y02 | D12: Pawl RH | E12: 0 | F12: 0 | G12: 0 | H12: 0 | I12: 0 | J12: 0 | K12: 0 | L12: 0 | M12: 0 | N12: 0 | O12: 0 | P12: 0 | Q12: 0 | R12: 0 | S12: 0 | T12: 0 | U12: 0 | V12: 0 | W12: 0 | X12: 0 | Y12: 0 | Z12: 0 | AA12: 0 | AB12: 0 | AC12: 0 | AD12: 0 | AE12: 0 | AF12: 0 | AG12: 0 | AH12: 0 | AI12: 0 | AJ12: 0
A13: 570 | B13: DTT002 | C13: 72534-X1Y03 | D13: Pawl LH | E13: 0 | F13: 0 | G13: 0 | H13: 0 | I13: 0 | J13: 0 | K13: 0 | L13: 0 | M13: 0 | N13: 0 | O13: 0 | P13: 0 | Q13: 0 | R13: 0 | S13: 0 | T13: 0 | U13: 0 | V13: 0 | W13: 0 | X13: 0 | Y13: 0 | Z13: 0 | AA13: 0 | AB13: 0 | AC13: 0 | AD13: 0 | AE13: 0 | AF13: 0 | AG13: 0 | AH13: 0 | AI13: 0 | AJ13: 0
A14: 570 | B14: DTT003 | C14: 72537-X1F00 | D14: Slide Cam | E14: 0 | F14: 0 | G14: 0 | H14: 0 | I14: 0 | J14: 0 | K14: 0 | L14: 0 | M14: 0 | N14: 0 | O14: 0 | P14: 0 | Q14: 0 | R14: 0 | S14: 0 | T14: 0 | U14: 0 | V14: 0 | W14: 0 | X14: 0 | Y14: 0 | Z14: 0 | AA14: 0 | AB14: 0 | AC14: 0 | AD14: 0 | AE14: 0 | AF14: 0 | AG14: 0 | AH14: 0 | AI14: 0 | AJ14: 0
A15: 570 | B15: TTC665 | C15: 89953-X1M14 | D15: Spring | E15: 0 | F15: 0 | G15: 0 | H15: 0 | I15: 0 | J15: 0 | K15: 0 | L15: 0 | M15: 0 | N15: 0 | O15: 0 | P15: 0 | Q15: 0 | R15: 0 | S15: 0 | T15: 0 | U15: 0 | V15: 0 | W15: 0 | X15: 0 | Y15: 0 | Z15: 0 | AA15: 0 | AB15: 0 | AC15: 0 | AD15: 0 | AE15: 0 | AF15: 0 | AG15: 0 | AH15: 0 | AI15: 0 | AJ15: 0
A16: 570 | B16: TTC644 | C16: 72537-X1M11 | D16: Hing Cam | E16: 0 | F16: 0 | G16: 0 | H16: 0 | I16: 0 | J16: 0 | K16: 0 | L16: 0 | M16: 0 | N16: 0 | O16: 0 | P16: 0 | Q16: 0 | R16: 0 | S16: 0 | T16: 0 | U16: 0 | V16: 0 | W16: 0 | X16: 0 | Y16: 0 | Z16: 0 | AA16: 0 | AB16: 0 | AC16: 0 | AD16: 0 | AE16: 0 | AF16: 0 | AG16: 0 | AH16: 0 | AI16: 0 | AJ16: 0
A17: 571-1 | B17: N32-18 | C17: 72523-X1M06 | D17: Guidde Plate | E17: 0 | F17: 2 | G17: 0 | H17: 0 | I17: 0 | J17: 0 | K17: 0 | L17: 0 | M17: 0 | N17: 0 | O17: 0 | P17: 2 | Q17: 0 | R17: 0 | S17: 0 | T17: 0 | U17: 0 | V17: 0 | W17: 0 | X17: 0 | Y17: 0 | Z17: 0 | AA17: 0 | AB17: 0 | AC17: 0 | AD17: 0 | AE17: 0 | AF17: 0 | AG17: 0 | AH17: 0 | AI17: 0 | AJ17: 4
A18: 571-1 | B18: N32-02 | C18: 72531-X1C02 | D18: Rachet | E18: 77 | F18: 384 | G18: 90 | H18: 23 | I18: 0 | J18: 0 | K18: 0 | L18: 27 | M18: 56 | N18: 16 | O18: 16 | P18: 44 | Q18: 0 | R18: 0 | S18: 42 | T18: 31 | U18: 16 | V18: 10 | W18: 12 | X18: 12 | Y18: 0 | Z18: 0 | AA18: 8 | AB18: 8 | AC18: 8 | AD18: 0 | AE18: 0 | AF18: 0 | AG18: 0 | AH18: 0 | AI18: 0 | AJ18: 880
A19: 571-1 | B19: N32-27 | C19: 72531-X1F00 | D19: Ring Plate | E19: 0 | F19: 0 | G19: 0 | H19: 0 | I19: 0 | J19: 0 | K19: 0 | L19: 0 | M19: 0 | N19: 0 | O19: 2 | P19: 0 | Q19: 0 | R19: 0 | S19: 0 | T19: 0 | U19: 0 | V19: 0 | W19: 0 | X19: 0 | Y19: 0 | Z19: 0 | AA19: 0 | AB19: 0 | AC19: 0 | AD19: 0 | AE19: 0 | AF19: 0 | AG19: 0 | AH19: 0 | AI19: 0 | AJ19: 2
A20: 571-1 | B20: DTT001 | C20: 72533-X1Y02 | D20: Pawl RH | E20: 0 | F20: 0 | G20: 0 | H20: 0 | I20: 0 | J20: 0 | K20: 0 | L20: 0 | M20: 0 | N20: 0 | O20: 0 | P20: 0 | Q20: 0 | R20: 0 | S20: 0 | T20: 0 | U20: 0 | V20: 0 | W20: 0 | X20: 0 | Y20: 0 | Z20: 0 | AA20: 0 | AB20: 0 | AC20: 0 | AD20: 0 | AE20: 0 | AF20: 0 | AG20: 0 | AH20: 0 | AI20: 0 | AJ20: 0
A21: 571-1 | B21: DTT002 | C21: 72534-X1Y03 | D21: Pawl LH | E21: 0 | F21: 0 | G21: 0 | H21: 0 | I21: 0 | J21: 0 | K21: 0 | L21: 0 | M21: 0 | N21: 0 | O21: 0 | P21: 0 | Q21: 0 | R21: 0 | S21: 0 | T21: 0 | U21: 0 | V21: 0 | W21: 0 | X21: 0 | Y21: 0 | Z21: 0 | AA21: 0 | AB21: 0 | AC21: 0 | AD21: 0 | AE21: 0 | AF21: 0 | AG21: 0 | AH21: 0 | AI21: 0 | AJ21: 0
A22: 571-1 | B22: DTT003 | C22: 72537-X1F00 | D22: Slide Cam | E22: 0 | F22: 0 | G22: 0 | H22: 0 | I22: 0 | J22: 0 | K22: 0 | L22: 0 | M22: 0 | N22: 0 | O22: 0 | P22: 0 | Q22: 0 | R22: 0 | S22: 0 | T22: 0 | U22: 0 | V22: 0 | W22: 0 | X22: 0 | Y22: 0 | Z22: 0 | AA22: 0 | AB22: 0 | AC22: 0 | AD22: 0 | AE22: 0 | AF22: 0 | AG22: 0 | AH22: 0 | AI22: 0 | AJ22: 0
A23: 571-1 | B23: TTC665 | C23: 89953-X1M14 | D23: Spring | E23: 0 | F23: 0 | G23: 0 | H23: 0 | I23: 0 | J23: 0 | K23: 0 | L23: 0 | M23: 0 | N23: 0 | O23: 0 | P23: 0 | Q23: 0 | R23: 0 | S23: 0 | T23: 0 | U23: 0 | V23: 0 | W23: 0 | X23: 0 | Y23: 0 | Z23: 0 | AA23: 0 | AB23: 0 | AC23: 0 | AD23: 0 | AE23: 0 | AF23: 0 | AG23: 0 | AH23: 0 | AI23: 0 | AJ23: 0
A24: 571-1 | B24: TTC644 | C24: 72537-X1M11 | D24: Hing Cam | E24: 0 | F24: 0 | G24: 0 | H24: 0 | I24: 0 | J24: 0 | K24: 0 | L24: 0 | M24: 0 | N24: 0 | O24: 0 | P24: 0 | Q24: 0 | R24: 0 | S24: 0 | T24: 0 | U24: 0 | V24: 0 | W24: 0 | X24: 0 | Y24: 0 | Z24: 0 | AA24: 0 | AB24: 0 | AC24: 0 | AD24: 0 | AE24: 0 | AF24: 0 | AG24: 0 | AH24: 0 | AI24: 0 | AJ24: 0
A25: 572 | B25: N32-18 | C25: 72523-X1M06 | D25: Guidde Plate | E25: 0 | F25: 0 | G25: 0 | H25: 0 | I25: 0 | J25: 0 | K25: 0 | L25: 0 | M25: 0 | N25: 0 | O25: 0 | P25: 0 | Q25: 0 | R25: 0 | S25: 0 | T25: 0 | U25: 0 | V25: 0 | W25: 0 | X25: 0 | Y25: 0 | Z25: 0 | AA25: 0 | AB25: 0 | AC25: 0 | AD25: 0 | AE25: 0 | AF25: 0 | AG25: 0 | AH25: 0 | AI25: 0 | AJ25: 0
A26: 572 | B26: N32-02 | C26: 72531-X1C02 | D26: Rachet | E26: 0 | F26: 0 | G26: 0 | H26: 0 | I26: 0 | J26: 0 | K26: 0 | L26: 0 | M26: 0 | N26: 0 | O26: 0 | P26: 0 | Q26: 0 | R26: 0 | S26: 0 | T26: 0 | U26: 0 | V26: 0 | W26: 0 | X26: 0 | Y26: 0 | Z26: 0 | AA26: 0 | AB26: 0 | AC26: 0 | AD26: 0 | AE26: 0 | AF26: 0 | AG26: 0 | AH26: 0 | AI26: 0 | AJ26: 0
A27: 572 | B27: N32-27 | C27: 72531-X1F00 | D27: Ring Plate | E27: 0 | F27: 0 | G27: 0 | H27: 0 | I27: 0 | J27: 0 | K27: 0 | L27: 0 | M27: 0 | N27: 0 | O27: 0 | P27: 0 | Q27: 0 | R27: 0 | S27: 0 | T27: 0 | U27: 0 | V27: 0 | W27: 0 | X27: 0 | Y27: 0 | Z27: 0 | AA27: 0 | AB27: 0 | AC27: 0 | AD27: 0 | AE27: 0 | AF27: 0 | AG27: 0 | AH27: 0 | AI27: 0 | AJ27: 0
A28: 572 | B28: DTT001 | C28: 72533-X1Y02 | D28: Pawl RH | E28: 0 | F28: 0 | G28: 0 | H28: 0 | I28: 0 | J28: 0 | K28: 0 | L28: 0 | M28: 0 | N28: 0 | O28: 0 | P28: 0 | Q28: 0 | R28: 0 | S28: 0 | T28: 0 | U28: 0 | V28: 0 | W28: 0 | X28: 0 | Y28: 0 | Z28: 0 | AA28: 0 | AB28: 0 | AC28: 0 | AD28: 0 | AE28: 0 | AF28: 0 | AG28: 0 | AH28: 0 | AI28: 0 | AJ28: 0
A29: 572 | B29: DTT002 | C29: 72534-X1Y03 | D29: Pawl LH | E29: 0 | F29: 0 | G29: 0 | H29: 0 | I29: 0 | J29: 0 | K29: 0 | L29: 0 | M29: 0 | N29: 0 | O29: 0 | P29: 0 | Q29: 0 | R29: 0 | S29: 0 | T29: 0 | U29: 0 | V29: 0 | W29: 0 | X29: 0 | Y29: 0 | Z29: 0 | AA29: 0 | AB29: 0 | AC29: 0 | AD29: 0 | AE29: 0 | AF29: 0 | AG29: 0 | AH29: 0 | AI29: 0 | AJ29: 0
A30: 572 | B30: DTT003 | C30: 72537-X1F00 | D30: Slide Cam | E30: 0 | F30: 0 | G30: 0 | H30: 0 | I30: 0 | J30: 0 | K30: 0 | L30: 0 | M30: 0 | N30: 0 | O30: 0 | P30: 0 | Q30: 0 | R30: 0 | S30: 0 | T30: 0 | U30: 0 | V30: 0 | W30: 0 | X30: 0 | Y30: 0 | Z30: 0 | AA30: 0 | AB30: 0 | AC30: 0 | AD30: 0 | AE30: 0 | AF30: 0 | AG30: 0 | AH30: 0 | AI30: 0 | AJ30: 0
A31: 572 | B31: TTC665 | C31: 89953-X1M14 | D31: Spring | E31: 0 | F31: 0 | G31: 0 | H31: 0 | I31: 0 | J31: 0 | K31: 0 | L31: 0 | M31: 0 | N31: 0 | O31: 0 | P31: 0 | Q31: 0 | R31: 0 | S31: 0 | T31: 0 | U31: 0 | V31: 0 | W31: 0 | X31: 0 | Y31: 0 | Z31: 0 | AA31: 0 | AB31: 0 | AC31: 0 | AD31: 0 | AE31: 0 | AF31: 0 | AG31: 0 | AH31: 0 | AI31: 0 | AJ31: 0
A32: 572 | B32: TTC644 | C32: 72537-X1M11 | D32: Hing Cam | E32: 0 | F32: 0 | G32: 0 | H32: 0 | I32: 0 | J32: 0 | K32: 0 | L32: 0 | M32: 0 | N32: 0 | O32: 0 | P32: 0 | Q32: 0 | R32: 0 | S32: 0 | T32: 0 | U32: 0 | V32: 0 | W32: 0 | X32: 0 | Y32: 0 | Z32: 0 | AA32: 0 | AB32: 0 | AC32: 0 | AD32: 0 | AE32: 0 | AF32: 0 | AG32: 0 | AH32: 0 | AI32: 0 | AJ32: 0
A33: 574 | B33: N32-18 | C33: 72523-X1M06 | D33: Guidde Plate | E33: 0 | F33: 0 | G33: 0 | H33: 0 | I33: 0 | J33: 0 | K33: 0 | L33: 0 | M33: 0 | N33: 0 | O33: 0 | P33: 0 | Q33: 0 | R33: 0 | S33: 0 | T33: 0 | U33: 0 | V33: 3 | W33: 0 | X33: 0 | Y33: 0 | Z33: 0 | AA33: 0 | AB33: 0 | AC33: 0 | AD33: 0 | AE33: 0 | AF33: 0 | AG33: 0 | AH33: 0 | AI33: 0 | AJ33: 3
A34: 574 | B34: N32-02 | C34: 72531-X1C02 | D34: Rachet | E34: 0 | F34: 0 | G34: 0 | H34: 0 | I34: 0 | J34: 0 | K34: 0 | L34: 0 | M34: 0 | N34: 0 | O34: 0 | P34: 0 | Q34: 0 | R34: 0 | S34: 0 | T34: 0 | U34: 0 | V34: 0 | W34: 0 | X34: 0 | Y34: 0 | Z34: 0 | AA34: 0 | AB34: 0 | AC34: 0 | AD34: 0 | AE34: 0 | AF34: 0 | AG34: 0 | AH34: 0 | AI34: 0 | AJ34: 0
A35: 574 | B35: N32-27 | C35: 72531-X1F00 | D35: Ring Plate | E35: 0 | F35: 0 | G35: 0 | H35: 0 | I35: 0 | J35: 0 | K35: 0 | L35: 0 | M35: 0 | N35: 0 | O35: 0 | P35: 0 | Q35: 0 | R35: 0 | S35: 0 | T35: 0 | U35: 0 | V35: 0 | W35: 0 | X35: 0 | Y35: 0 | Z35: 0 | AA35: 0 | AB35: 0 | AC35: 0 | AD35: 0 | AE35: 0 | AF35: 0 | AG35: 0 | AH35: 0 | AI35: 0 | AJ35: 0
A36: 574 | B36: DTT001 | C36: 72533-X1Y02 | D36: Pawl RH | E36: 0 | F36: 0 | G36: 0 | H36: 0 | I36: 0 | J36: 0 | K36: 0 | L36: 0 | M36: 0 | N36: 0 | O36: 0 | P36: 0 | Q36: 0 | R36: 0 | S36: 0 | T36: 0 | U36: 0 | V36: 0 | W36: 0 | X36: 0 | Y36: 0 | Z36: 0 | AA36: 0 | AB36: 0 | AC36: 0 | AD36: 0 | AE36: 0 | AF36: 0 | AG36: 0 | AH36: 0 | AI36: 0 | AJ36: 0
... A56: 575 | B56: AR0-02-T | C56: 72520-X1M16 | D56: TEST MC | E56: 0 | F56: 0 | G56: 0 | H56: 0 | I56: 0 | J56: 0 | K56: 0 | L56: 0 | M56: 0 | N56: 0 | O56: 0 | P56: 0 | Q56: 0 | R56: 0 | S56: 0 | T56: 0 | U56: 0 | V56: 0 | W56: 0 | X56: 0 | Y56: 0 | Z56: 0 | AA56: 0 | AB56: 0 | AC56: 0 | AD56: 0 | AE56: 0 | AF56: 0 | AG56: 0 | AH56: 0 | AI56: 0 | AJ56: 0
A57: CFR,CFL | B57: TTC668 | C57: 72510-X1302 | D57: ADJUSTER ASSY, FR SEAT RECLINING, RH | E57: 0 | F57: 0 | G57: 0 | H57: 0 | I57: 0 | J57: 0 | K57: 0 | L57: 0 | M57: 0 | N57: 0 | O57: 0 | P57: 0 | Q57: 0 | R57: 0 | S57: 0 | T57: 0 | U57: 0 | V57: 0 | W57: 0 | X57: 0 | Y57: 0 | Z57: 0 | AA57: 0 | AB57: 0 | AC57: 0 | AD57: 0 | AE57: 0 | AF57: 0 | AG57: 0 | AH57: 0 | AI57: 0 | AJ57: 0
A58: CFR,CFL | B58: AR0-02 | C58: 72520-X1M16 | D58: ADJUSTER ASSY, FR SEAT RECLINING, LH | E58: 0 | F58: 0 | G58: 0 | H58: 0 | I58: 0 | J58: 0 | K58: 0 | L58: 0 | M58: 0 | N58: 0 | O58: 0 | P58: 0 | Q58: 0 | R58: 0 | S58: 0 | T58: 0 | U58: 0 | V58: 0 | W58: 0 | X58: 0 | Y58: 0 | Z58: 0 | AA58: 0 | AB58: 0 | AC58: 0 | AD58: 0 | AE58: 0 | AF58: 0 | AG58: 0 | AH58: 0 | AI58: 0 | AJ58: 0
A59: CFR,CFL | B59: CFP-12 | C59: 72524-X1C01 | D59: PLATE, RECLINING ADJUSTER LWR ARM, LH | E59: 0 | F59: 0 | G59: 0 | H59: 0 | I59: 0 | J59: 0 | K59: 0 | L59: 0 | M59: 0 | N59: 0 | O59: 0 | P59: 0 | Q59: 0 | R59: 0 | S59: 0 | T59: 0 | U59: 0 | V59: 0 | W59: 0 | X59: 0 | Y59: 0 | Z59: 0 | AA59: 0 | AB59: 0 | AC59: 0 | AD59: 0 | AE59: 0 | AF59: 0 | AG59: 0 | AH59: 0 | AI59: 0 | AJ59: 0
...

Sheet Sheet2
A1: Line | B1: SD code | C1: Part number | D1: Partname
A2: 20 | B2: CRC-56 | C2: =VLOOKUP(B2,Append2!B:D,2,FALSE) -> 0 | D2: =VLOOKUP(B2,Append2!B:D,3,FALSE) -> ROD SUB-ASSY, RECLINING CONNECTING
A3: 20 | B3: GB0-02 | C3: =VLOOKUP(B3,Append2!B:D,2,FALSE) -> 72211-0K050 | D3: =VLOOKUP(B3,Append2!B:D,3,FALSE) -> 2ND HANDLE 4
A4: 20 | B4: GB0-02-T | C4: =VLOOKUP(B4,Append2!B:D,2,FALSE) -> 0 | D4: =VLOOKUP(B4,Append2!B:D,3,FALSE) -> TEST MC
A5: 20 | B5: IRD-63 | C5: =VLOOKUP(B5,Append2!B:D,2,FALSE) -> 72506-X7A04 | D5: =VLOOKUP(B5,Append2!B:D,3,FALSE) -> ROD SUB-ASSY, RECLINING CONNECTING
A6: 20 | B6: IRD-64 | C6: =VLOOKUP(B6,Append2!B:D,2,FALSE) -> 72506-X7V00 | D6: =VLOOKUP(B6,Append2!B:D,3,FALSE) -> ROD SUB-ASSY, RECLINING CONNECTING
A7: 20 | B7: IRD-77 | C7: =VLOOKUP(B7,Append2!B:D,2,FALSE) -> 72659-X7A09 | D7: =VLOOKUP(B7,Append2!B:D,3,FALSE) -> ROD RR SEAT BACK LOCK CONNECTING
A8: 20 | B8: TOP-311 | C8: =VLOOKUP(B8,Append2!B:D,2,FALSE) -> 0 | D8: =VLOOKUP(B8,Append2!B:D,3,FALSE) -> 0
A9: 570 | B9: DTT001 | C9: =VLOOKUP(B9,Append2!B:D,2,FALSE) -> 72533-X1Y02 | D9: =VLOOKUP(B9,Append2!B:D,3,FALSE) -> Pawl RH
A10: 570 | B10: DTT002 | C10: =VLOOKUP(B10,Append2!B:D,2,FALSE) -> 72534-X1Y03 | D10: =VLOOKUP(B10,Append2!B:D,3,FALSE) -> Pawl LH
A11: 570 | B11: DTT003 | C11: =VLOOKUP(B11,Append2!B:D,2,FALSE) -> 72537-X1F00 | D11: =VLOOKUP(B11,Append2!B:D,3,FALSE) -> Slide Cam
A12: 570 | B12: N32-02 | C12: =VLOOKUP(B12,Append2!B:D,2,FALSE) -> 72531-X1C02 | D12: =VLOOKUP(B12,Append2!B:D,3,FALSE) -> Rachet
A13: 570 | B13: N32-18 | C13: =VLOOKUP(B13,Append2!B:D,2,FALSE) -> 72523-X1M06 | D13: =VLOOKUP(B13,Append2!B:D,3,FALSE) -> Guidde Plate
... A48: 575 | B48: TTC665 | C48: =VLOOKUP(B48,Append2!B:D,2,FALSE) -> 89953-X1M14 | D48: =VLOOKUP(B48,Append2!B:D,3,FALSE) -> Spring
A49: 571-1 | B49: DTT001 | C49: =VLOOKUP(B49,Append2!B:D,2,FALSE) -> 72533-X1Y02 | D49: =VLOOKUP(B49,Append2!B:D,3,FALSE) -> Pawl RH
A50: 571-2 | B50: DTT002 | C50: =VLOOKUP(B50,Append2!B:D,2,FALSE) -> 72534-X1Y03 | D50: =VLOOKUP(B50,Append2!B:D,3,FALSE) -> Pawl LH
A51: 571-3 | B51: DTT003 | C51: =VLOOKUP(B51,Append2!B:D,2,FALSE) -> 72537-X1F00 | D51: =VLOOKUP(B51,Append2!B:D,3,FALSE) -> Slide Cam
A52: 571-4 | B52: N32-02 | C52: =VLOOKUP(B52,Append2!B:D,2,FALSE) -> 72531-X1C02 | D52: =VLOOKUP(B52,Append2!B:D,3,FALSE) -> Rachet
A53: 571-5 | B53: N32-18 | C53: =VLOOKUP(B53,Append2!B:D,2,FALSE) -> 72523-X1M06 | D53: =VLOOKUP(B53,Append2!B:D,3,FALSE) -> Guidde Plate
A54: 571-6 | B54: N32-27 | C54: =VLOOKUP(B54,Append2!B:D,2,FALSE) -> 72531-X1F00 | D54: =VLOOKUP(B54,Append2!B:D,3,FALSE) -> Ring Plate
A55: 571-7 | B55: TTC644 | C55: =VLOOKUP(B55,Append2!B:D,2,FALSE) -> 72537-X1M11 | D55: =VLOOKUP(B55,Append2!B:D,3,FALSE) -> Hing Cam
A56: 571-8 | B56: TTC665 | C56: =VLOOKUP(B56,Append2!B:D,2,FALSE) -> 89953-X1M14 | D56: =VLOOKUP(B56,Append2!B:D,3,FALSE) -> Spring
A57: CFR,CFL | B57: AR0-01 | C57: =VLOOKUP(B57,Append2!B:D,2,FALSE) -> 72510-X1M15 | D57: =VLOOKUP(B57,Append2!B:D,3,FALSE) -> ADJUSTER ASSY, FR SEAT RECLINING, RH
A58: CFR,CFL | B58: AR0-02 | C58: =VLOOKUP(B58,Append2!B:D,2,FALSE) -> 72520-X1M16 | D58: =VLOOKUP(B58,Append2!B:D,3,FALSE) -> ADJUSTER ASSY, FR SEAT RECLINING, LH
A59: CFR,CFL | B59: BTS071 | C59: =VLOOKUP(B59,Append2!B:D,2,FALSE) -> 79716-X1400 | D59: =VLOOKUP(B59,Append2!B:D,3,FALSE) -> NUT
A60: CFR,CFL | B60: CFL-16 | C60: =VLOOKUP(B60,Append2!B:D,2,FALSE) -> 71104-X1408 | D60: =VLOOKUP(B60,Append2!B:D,3,FALSE) -> FRAME SUB-ASSY, FR SEAT BACK MAIN, LH
... A2254: TTUS | B2254: TTU-S4-T | C2254: =VLOOKUP(B2254,Append2!B:D,2,FALSE) -> TTU-S4 | D2254: =VLOOKUP(B2254,Append2!B:D,3,FALSE) -> TEST MC , TEST ทำลาย
